Workbook

Sheet Сводка
A1: Снижают ли расценки ниже подписанных? — Да, по 2 позициям ДС №1 и по ряду новых работ
A2: Все цифры — формулы по листу «Позиции». Без НДС.
A4: Документы
A5: Договор № СПБ-ГАЗЭ/ОВ/7-9 от 19.06.2026, Прил.1 (7–9 эт.) | B5: 8698406.7 | C5: подписан в Диадок 01–07.07.2026
A6: ДС №1 от 27.07.2026, Прил.1 (3, 7–9 эт.) — заменяет Прил.1 | B6: 13716755 | C6: подписано в Диадок 04.08.2026; оплачено 5 398 522,20
A7: Наше КП (2, 3, 7–10 эт.) | B7: =SUM(Позиции!$K$6:$K$332) -> 22665254 | C7: исходное
A8: Файл заказчика — как у них посчитано | B8: 16526808 | C8: итог из их файла
A9: Файл заказчика — с учётом всех их комментариев | B9: =SUM(Позиции!$N$6:$N$332) -> 16074197 | C9: + снижения, внесённые только в комментарии
A10: НАША ПОЗИЦИЯ ПО ПИСЬМУ (с дымоудалением) | B10: =SUM(Позиции!$Y$6:$Y$332) -> 21418972 | C10: письмо с возражениями: вернуть 4 316 295,16 + дымоудаление 1 028 480 допником
A12: Разделы 1–2 (работы по подписанному ДС №1) против разделов 3–7 (новые работы)
A13: Блок | B13: По ДС №1 (подписано), ₽ | C13: Наше КП, ₽ | D13: Заказчик, ₽ | E13: Заказчик против КП, ₽ | F13: По нашему письму, ₽
A14: Разделы 1–2 (3, 7–9 эт.) — по ДС №1 | B14: =SUMIFS(Позиции!$G$6:$G$332,Позиции!$A$6:$A$332,"1. *")+SUMIFS(Позиции!$G$6:$G$332,Позиции!$A$6:$A$332,"2. *") -> 13716755 | C14: =SUMIFS(Позиции!$K$6:$K$332,Позиции!$A$6:$A$332,"1. *")+SUMIFS(Позиции!$K$6:$K$332,Позиции!$A$6:$A$332,"2. *") -> 13040299 | D14: =SUMIFS(Позиции!$N$6:$N$332,Позиции!$A$6:$A$332,"1. *")+SUMIFS(Позиции!$N$6:$N$332,Позиции!$A$6:$A$332,"2. *") -> 11232724 | E14: =D14-C14 -> -1807575 | F14: =SUMIFS(Позиции!$Y$6:$Y$332,Позиции!$A$6:$A$332,"1. *")+SUMIFS(Позиции!$Y$6:$Y$332,Позиции!$A$6:$A$332,"2. *") -> 12728299
A15: Разделы 3–7 — новые работы (10 и 2 эт., доп. работы, дымоудаление) | B15: — | C15: =SUM(Позиции!$K$6:$K$332)-C14 -> 9624955.2 | D15: =SUM(Позиции!$N$6:$N$332)-D14 -> 4841473.2 | E15: =D15-C15 -> -4783482 | F15: =SUM(Позиции!$Y$6:$Y$332)-F14 -> 8690673.4
A16: Итого | B16: =B14 -> 13716755 | C16: =C14+C15 -> 22665254 | D16: =D14+D15 -> 16074197 | E16: =E14+E15 -> -6591057 | F16: =F14+F15 -> 21418972
A17: В разделах 1–2 наше КП меньше ДС №1, потому что объёмы пересчитаны по факту, а 9 позиций мы сами пометили «исключено». «По нашему письму» включает дымоудаление (1 028 480), которое уйдёт в отдельный допник.
A18: Главные выводы
A19: Вывод | B19: Позиций | C19: Сумма, ₽ | D19: Что это значит
A20: НИЖЕ подписанной цены ДС №1 | B20: =COUNTIF(Позиции!$T$6:$T$332,A20) -> 2 | C20: =SUMIFS(Позиции!$R$6:$R$332,Позиции!$T$6:$T$332,A20) -> -1495575 | D20: Заказчик снизил цены, которые уже подписаны в ДС №1 (п. 2.7 узел регулирования 6 650 → 2 500; п. 1.33 K-Flex 665,89 → 570). По п. 10.1 Договора цену меняет только ДС, подписанное обеими сторонами.
A21: Новая работа: НИЖЕ цены аналога из ДС | B21: =COUNTIF(Позиции!$T$6:$T$332,A21) -> 16 | C21: =SUMIFS(Позиции!$R$6:$R$332,Позиции!$T$6:$T$332,A21) -> -74399.98 | D21: Новые работы, где заказчик пишет «по договору», а ставит ниже того же изделия в ДС №1: решётки защитные (в ДС 1 425), круглые фасонные изделия (в ДС 855).
A22: Удалено заказчиком без комментария | B22: =COUNTIF(Позиции!$T$6:$T$332,A22) -> 6 | C22: =SUMIFS(Позиции!$S$6:$S$332,Позиции!$T$6:$T$332,A22) -> -1151370 | D22: Дренаж, демонтажи, подключение фанкойлов — просто вычеркнуты.
A23: Перенесено в отдельный допник | B23: =COUNTIF(Позиции!$T$6:$T$332,A23) -> 8 | C23: =SUMIFS(Позиции!$S$6:$S$332,Позиции!$T$6:$T$332,A23) -> -1028480 | D23: Дымоудаление 10 и 2 эт. — нужен подписанный допник.
A24: Заказчик прав: вернул цену ДС №1 | B24: =COUNTIF(Позиции!$T$6:$T$332,A24) -> 4 | C24: =SUMIFS(Позиции!$S$6:$S$332,Позиции!$T$6:$T$332,A24) -> -312000 | D24: Тут ошиблись мы: в КП было 500 и 200 ₽, а в ДС №1 — 400 и 150 ₽ (PEX 25/32, Armaflex 28/35). Спорить не стоит.
A25: Новая работа: по цене аналога ДС (снижено с нашей) | B25: =COUNTIF(Позиции!$T$6:$T$332,A25) -> 61 | C25: =SUMIFS(Позиции!$S$6:$S$332,Позиции!$T$6:$T$332,A25) -> -139881.81 | D25: Заказчик снизил наши цены до цены такого же изделия в ДС №1 (гофра 760, КВК 950, фасонка 855, воздуховоды и т.д.). У заказчика здесь сильная позиция.
A26: Новая работа: выше аналога ДС | B26: =COUNTIF(Позиции!$T$6:$T$332,A26) -> 12 | C26: =SUMIFS(Позиции!$S$6:$S$332,Позиции!$T$6:$T$332,A26) -> -199677.66 | D26: Заказчик оставил цену выше, чем в ДС (PEX, теплоизоляция трубок, часть воздуховодов). В нашу пользу, но могут пересмотреть.
A27: Новая работа: аналога в ДС нет — снижено | B27: =COUNTIF(Позиции!$T$6:$T$332,A27) -> 90 | C27: =SUMIFS(Позиции!$S$6:$S$332,Позиции!$T$6:$T$332,A27) -> -2138990.4 | D27: Цены на новые работы — предмет торга; договорной цены нет.
A28: Для строк 1–2 «Сумма» = цена заказчика против цены ДС/аналога × объём заказчика; для остальных — разница с нашим КП.
A29: Исключено нами, но есть в ДС №1 (по ценам ДС) | C29: =SUMPRODUCT((Позиции!$T$6:$T$332="Исключено нами (в ДС есть)")*1,Позиции!$G$6:$G$332) -> 912914.4 | D29: 9 позиций ДС №1 мы сами пометили «исключено» (из них пайка кондиционеров п.2.14 — 646 000). Если работы выполнены — их надо вернуть в КП.

Sheet Ниже договора
A1: Позиции, где цена заказчика ниже подписанной цены или цены аналога из ДС №1
A3: № | B3: Наименование | C3: Ед. | D3: Кол-во (заказчик) | E3: Цена ДС / аналога, ₽ | F3: Откуда | G3: Цена заказчика, ₽ | H3: Потеря на ед., ₽ | I3: Потеря на объём, ₽ | J3: Вывод | K3: Комментарий
A4: =IF(Позиции!B47="","",Позиции!B47) -> 2.7 | B4: =IF(Позиции!C47="","",Позиции!C47) -> Узел регулирования климатической балки 1/2 Modulator ½ | C4: =IF(Позиции!D47="","",Позиции!D47) -> шт. | D4: =IF(Позиции!L47="","",Позиции!L47) -> 340 | E4: =IF(Позиции!O47="","",Позиции!O47) -> 6650 | F4: =IF(Позиции!P47="","",Позиции!P47) -> ДС №1 п.2.7 | G4: =IF(Позиции!M47="","",Позиции!M47) -> 2500 | H4: =IF(Позиции!Q47="","",Позиции!Q47) -> -4150 | I4: =IF(Позиции!R47="","",Позиции!R47) -> -1411000 | J4: =IF(Позиции!T47="","",Позиции!T47) -> НИЖЕ подписанной цены ДС №1 | K4: =IF(Позиции!U47="","",Позиции!U47) -> Заказчик: по договоренности | В исходном Договоре (п.11.2 Смесительный узел): 5 000.00 ₽
A5: =IF(Позиции!B38="","",Позиции!B38) -> 1.33 | B5: =IF(Позиции!C38="","",Позиции!C38) -> Универсальная теплоизоляция в виде рулонов, толщиной 6 мм K- Flex-ST | C5: =IF(Позиции!D38="","",Позиции!D38) -> м2 | D5: =IF(Позиции!L38="","",Позиции!L38) -> 882 | E5: =IF(Позиции!O38="","",Позиции!O38) -> 665.89 | F5: =IF(Позиции!P38="","",Позиции!P38) -> ДС №1 п.1.33 | G5: =IF(Позиции!M38="","",Позиции!M38) -> 570 | H5: =IF(Позиции!Q38="","",Позиции!Q38) -> -95.89 | I5: =IF(Позиции!R38="","",Позиции!R38) -> -84574.98 | J5: =IF(Позиции!T38="","",Позиции!T38) -> НИЖЕ подписанной цены ДС №1 | K5: =IF(Позиции!U38="","",Позиции!U38) -> Заказчик: р по договору
A6: =IF(Позиции!B244="","",Позиции!B244) -> 6.3 | B6: =IF(Позиции!C244="","",Позиции!C244) -> Решетка защитная круглая, Ø200 БСК 200 | C6: =IF(Позиции!D244="","",Позиции!D244) -> шт. | D6: =IF(Позиции!L244="","",Позиции!L244) -> 44 | E6: =IF(Позиции!O244="","",Позиции!O244) -> 1425 | F6: =IF(Позиции!P244="","",Позиции!P244) -> ДС п.2.2–2.3 (решётка защитная круглая) | G6: =IF(Позиции!M244="","",Позиции!M244) -> 298.89 | H6: =IF(Позиции!Q244="","",Позиции!Q244) -> -1126.11 | I6: =IF(Позиции!R244="","",Позиции!R244) -> -49548.84 | J6: =IF(Позиции!T244="","",Позиции!T244) -> Новая работа: НИЖЕ цены аналога из ДС | K6: =IF(Позиции!U244="","",Позиции!U244) -> Заказчик: по договору
A7: =IF(Позиции!B171="","",Позиции!B171) -> 4.57 | B7: =IF(Позиции!C171="","",Позиции!C171) -> Врезка плоская из оцинкованной стали толщиной 0,5мм, класса «В», Ø160 | C7: =IF(Позиции!D171="","",Позиции!D171) -> шт. | D7: =IF(Позиции!L171="","",Позиции!L171) -> 14 | E7: =IF(Позиции!O171="","",Позиции!O171) -> 855 | F7: =IF(Позиции!P171="","",Позиции!P171) -> ДС п.1.17–1.30 (круглые фасонные 855) | G7: =IF(Позиции!M171="","",Позиции!M171) -> 370 | H7: =IF(Позиции!Q171="","",Позиции!Q171) -> -485 | I7: =IF(Позиции!R171="","",Позиции!R171) -> -6790 | J7: =IF(Позиции!T171="","",Позиции!T171) -> Новая работа: НИЖЕ цены аналога из ДС | K7: =IF(Позиции!U171="","",Позиции!U171)
A8: =IF(Позиции!B172="","",Позиции!B172) -> 4.58 | B8: =IF(Позиции!C172="","",Позиции!C172) -> Врезка плоская из оцинкованной стали толщиной 0,5мм, класса «В», Ø200 | C8: =IF(Позиции!D172="","",Позиции!D172) -> шт. | D8: =IF(Позиции!L172="","",Позиции!L172) -> 12 | E8: =IF(Позиции!O172="","",Позиции!O172) -> 855 | F8: =IF(Позиции!P172="","",Позиции!P172) -> ДС п.1.17–1.30 (круглые фасонные 855) | G8: =IF(Позиции!M172="","",Позиции!M172) -> 370 | H8: =IF(Позиции!Q172="","",Позиции!Q172) -> -485 | I8: =IF(Позиции!R172="","",Позиции!R172) -> -5820 | J8: =IF(Позиции!T172="","",Позиции!T172) -> Новая работа: НИЖЕ цены аналога из ДС | K8: =IF(Позиции!U172="","",Позиции!U172)
A9: =IF(Позиции!B242="","",Позиции!B242) -> 6.1 | B9: =IF(Позиции!C242="","",Позиции!C242) -> Решетка защитная круглая, Ø100 БСК 100 | C9: =IF(Позиции!D242="","",Позиции!D242) -> шт. | D9: =IF(Позиции!L242="","",Позиции!L242) -> 3 | E9: =IF(Позиции!O242="","",Позиции!O242) -> 1425 | F9: =IF(Позиции!P242="","",Позиции!P242) -> ДС п.2.2–2.3 (решётка защитная круглая) | G9: =IF(Позиции!M242="","",Позиции!M242) -> 185 | H9: =IF(Позиции!Q242="","",Позиции!Q242) -> -1240 | I9: =IF(Позиции!R242="","",Позиции!R242) -> -3720 | J9: =IF(Позиции!T242="","",Позиции!T242) -> Новая работа: НИЖЕ цены аналога из ДС | K9: =IF(Позиции!U242="","",Позиции!U242) -> Заказчик: по договору
A10: =IF(Позиции!B175="","",Позиции!B175) -> 4.61 | B10: =IF(Позиции!C175="","",Позиции!C175) -> Врезка-седло из оцинкованной стали толщиной 0,5мм, класса «В», Ø200/Ø160 | C10: =IF(Позиции!D175="","",Позиции!D175) -> шт. | D10: =IF(Позиции!L175="","",Позиции!L175) -> 3 | E10: =IF(Позиции!O175="","",Позиции!O175) -> 855 | F10: =IF(Позиции!P175="","",Позиции!P175) -> ДС п.1.17–1.30 (круглые фасонные 855) | G10: =IF(Позиции!M175="","",Позиции!M175) -> 370 | H10: =IF(Позиции!Q175="","",Позиции!Q175) -> -485 | I10: =IF(Позиции!R175="","",Позиции!R175) -> -1455 | J10: =IF(Позиции!T175="","",Позиции!T175) -> Новая работа: НИЖЕ цены аналога из ДС | K10: =IF(Позиции!U175="","",Позиции!U175)
A11: =IF(Позиции!B243="","",Позиции!B243) -> 6.2 | B11: =IF(Позиции!C243="","",Позиции!C243) -> Решетка защитная круглая, Ø160 БСК 160 | C11: =IF(Позиции!D243="","",Позиции!D243) -> шт. | D11: =IF(Позиции!L243="","",Позиции!L243) -> 1 | E11: =IF(Позиции!O243="","",Позиции!O243) -> 1425 | F11: =IF(Позиции!P243="","",Позиции!P243) -> ДС п.2.2–2.3 (решётка защитная круглая) | G11: =IF(Позиции!M243="","",Позиции!M243) -> 205.66 | H11: =IF(Позиции!Q243="","",Позиции!Q243) -> -1219.34 | I11: =IF(Позиции!R243="","",Позиции!R243) -> -1219.34 | J11: =IF(Позиции!T243="","",Позиции!T243) -> Новая работа: НИЖЕ цены аналога из ДС | K11: =IF(Позиции!U243="","",Позиции!U243) -> Заказчик: по договору
A12: =IF(Позиции!B266="","",Позиции!B266) -> 6.25 | B12: =IF(Позиции!C266="","",Позиции!C266) -> Отвод 150 из оцинкованной стали толщиной 0,5мм, класса «В», Ø200 | C12: =IF(Позиции!D266="","",Позиции!D266) -> шт. | D12: =IF(Позиции!L266="","",Позиции!L266) -> 2 | E12: =IF(Позиции!O266="","",Позиции!O266) -> 855 | F12: =IF(Позиции!P266="","",Позиции!P266) -> ДС п.1.17–1.30 (круглые фасонные 855) | G12: =IF(Позиции!M266="","",Позиции!M266) -> 340 | H12: =IF(Позиции!Q266="","",Позиции!Q266) -> -515 | I12: =IF(Позиции!R266="","",Позиции!R266) -> -1030 | J12: =IF(Позиции!T266="","",Позиции!T266) -> Новая работа: НИЖЕ цены аналога из ДС | K12: =IF(Позиции!U266="","",Позиции!U266)
A13: =IF(Позиции!B170="","",Позиции!B170) -> 4.56 | B13: =IF(Позиции!C170="","",Позиции!C170) -> Врезка плоская из оцинкованной стали толщиной 0,5мм, класса «В», Ø100 | C13: =IF(Позиции!D170="","",Позиции!D170) -> шт. | D13: =IF(Позиции!L170="","",Позиции!L170) -> 2 | E13: =IF(Позиции!O170="","",Позиции!O170) -> 855 | F13: =IF(Позиции!P170="","",Позиции!P170) -> ДС п.1.17–1.30 (круглые фасонные 855) | G13: =IF(Позиции!M170="","",Позиции!M170) -> 370 | H13: =IF(Позиции!Q170="","",Позиции!Q170) -> -485 | I13: =IF(Позиции!R170="","",Позиции!R170) -> -970 | J13: =IF(Позиции!T170="","",Позиции!T170) -> Новая работа: НИЖЕ цены аналога из ДС | K13: =IF(Позиции!U170="","",Позиции!U170)
A14: =IF(Позиции!B177="","",Позиции!B177) -> 4.63 | B14: =IF(Позиции!C177="","",Позиции!C177) -> Переход из оцинкованной стали толщиной 0,5мм, класса «В», Ø125/Ø100 | C14: =IF(Позиции!D177="","",Позиции!D177) -> шт. | D14: =IF(Позиции!L177="","",Позиции!L177) -> 2 | E14: =IF(Позиции!O177="","",Позиции!O177) -> 855 | F14: =IF(Позиции!P177="","",Позиции!P177) -> ДС п.1.17–1.30 (круглые фасонные 855) | G14: =IF(Позиции!M177="","",Позиции!M177) -> 370 | H14: =IF(Позиции!Q177="","",Позиции!Q177) -> -485 | I14: =IF(Позиции!R177="","",Позиции!R177) -> -970 | J14: =IF(Позиции!T177="","",Позиции!T177) -> Новая работа: НИЖЕ цены аналога из ДС | K14: =IF(Позиции!U177="","",Позиции!U177)
A15: =IF(Позиции!B173="","",Позиции!B173) -> 4.59 | B15: =IF(Позиции!C173="","",Позиции!C173) -> Врезка-седло из оцинкованной стали толщиной 0,5мм, класса «В», Ø160/Ø100 | C15: =IF(Позиции!D173="","",Позиции!D173) -> шт. | D15: =IF(Позиции!L173="","",Позиции!L173) -> 1 | E15: =IF(Позиции!O173="","",Позиции!O173) -> 855 | F15: =IF(Позиции!P173="","",Позиции!P173) -> ДС п.1.17–1.30 (круглые фасонные 855) | G15: =IF(Позиции!M173="","",Позиции!M173) -> 370 | H15: =IF(Позиции!Q173="","",Позиции!Q173) -> -485 | I15: =IF(Позиции!R173="","",Позиции!R173) -> -485 | J15: =IF(Позиции!T173="","",Позиции!T173) -> Новая работа: НИЖЕ цены аналога из ДС | K15: =IF(Позиции!U173="","",Позиции!U173)
A16: =IF(Позиции!B174="","",Позиции!B174) -> 4.60 | B16: =IF(Позиции!C174="","",Позиции!C174) -> Врезка-седло из оцинкованной стали толщиной 0,5мм, класса «В», Ø160/Ø125 | C16: =IF(Позиции!D174="","",Позиции!D174) -> шт. | D16: =IF(Позиции!L174="","",Позиции!L174) -> 1 | E16: =IF(Позиции!O174="","",Позиции!O174) -> 855 | F16: =IF(Позиции!P174="","",Позиции!P174) -> ДС п.1.17–1.30 (круглые фасонные 855) | G16: =IF(Позиции!M174="","",Позиции!M174) -> 370 | H16: =IF(Позиции!Q174="","",Позиции!Q174) -> -485 | I16: =IF(Позиции!R174="","",Позиции!R174) -> -485 | J16: =IF(Позиции!T174="","",Позиции!T174) -> Новая работа: НИЖЕ цены аналога из ДС | K16: =IF(Позиции!U174="","",Позиции!U174)
A17: =IF(Позиции!B176="","",Позиции!B176) -> 4.62 | B17: =IF(Позиции!C176="","",Позиции!C176) -> Тройник из оцинкованной стали толщиной 0,5мм, класса «В», Ø125/Ø125/Ø125 | C17: =IF(Позиции!D176="","",Позиции!D176) -> шт. | D17: =IF(Позиции!L176="","",Позиции!L176) -> 1 | E17: =IF(Позиции!O176="","",Позиции!O176) -> 855 | F17: =IF(Позиции!P176="","",Позиции!P176) -> ДС п.1.17–1.30 (круглые фасонные 855) | G17: =IF(Позиции!M176="","",Позиции!M176) -> 370 | H17: =IF(Позиции!Q176="","",Позиции!Q176) -> -485 | I17: =IF(Позиции!R176="","",Позиции!R176) -> -485 | J17: =IF(Позиции!T176="","",Позиции!T176) -> Новая работа: НИЖЕ цены аналога из ДС | K17: =IF(Позиции!U176="","",Позиции!U176)
A18: =IF(Позиции!B178="","",Позиции!B178) -> 4.64 | B18: =IF(Позиции!C178="","",Позиции!C178) -> Переход из оцинкованной стали толщиной 0,5мм, класса «В», Ø160/Ø100 | C18: =IF(Позиции!D178="","",Позиции!D178) -> шт. | D18: =IF(Позиции!L178="","",Позиции!L178) -> 1 | E18: =IF(Позиции!O178="","",Позиции!O178) -> 855 | F18: =IF(Позиции!P178="","",Позиции!P178) -> ДС п.1.17–1.30 (круглые фасонные 855) | G18: =IF(Позиции!M178="","",Позиции!M178) -> 370 | H18: =IF(Позиции!Q178="","",Позиции!Q178) -> -485 | I18: =IF(Позиции!R178="","",Позиции!R178) -> -485 | J18: =IF(Позиции!T178="","",Позиции!T178) -> Новая работа: НИЖЕ цены аналога из ДС | K18: =IF(Позиции!U178="","",Позиции!U178)
A19: =IF(Позиции!B179="","",Позиции!B179) -> 4.65 | B19: =IF(Позиции!C179="","",Позиции!C179) -> Переход из оцинкованной стали толщиной 0,5мм, класса «В», Ø160/Ø125 | C19: =IF(Позиции!D179="","",Позиции!D179) -> шт. | D19: =IF(Позиции!L179="","",Позиции!L179) -> 1 | E19: =IF(Позиции!O179="","",Позиции!O179) -> 855 | F19: =IF(Позиции!P179="","",Позиции!P179) -> ДС п.1.17–1.30 (круглые фасонные 855) | G19: =IF(Позиции!M179="","",Позиции!M179) -> 440 | H19: =IF(Позиции!Q179="","",Позиции!Q179) -> -415 | I19: =IF(Позиции!R179="","",Позиции!R179) -> -415 | J19: =IF(Позиции!T179="","",Позиции!T179) -> Новая работа: НИЖЕ цены аналога из ДС | K19: =IF(Позиции!U179="","",Позиции!U179)
A20: =IF(Позиции!B180="","",Позиции!B180) -> 4.66 | B20: =IF(Позиции!C180="","",Позиции!C180) -> Переход из оцинкованной стали толщиной 0,5мм, класса «В», Ø200/Ø160 | C20: =IF(Позиции!D180="","",Позиции!D180) -> шт. | D20: =IF(Позиции!L180="","",Позиции!L180) -> 1 | E20: =IF(Позиции!O180="","",Позиции!O180) -> 855 | F20: =IF(Позиции!P180="","",Позиции!P180) -> ДС п.1.17–1.30 (круглые фасонные 855) | G20: =IF(Позиции!M180="","",Позиции!M180) -> 440 | H20: =IF(Позиции!Q180="","",Позиции!Q180) -> -415 | I20: =IF(Позиции!R180="","",Позиции!R180) -> -415 | J20: =IF(Позиции!T180="","",Позиции!T180) -> Новая работа: НИЖЕ цены аналога из ДС | K20: =IF(Позиции!U180="","",Позиции!U180)
A21: =IF(Позиции!B196="","",Позиции!B196) -> 4.82 | B21: =IF(Позиции!C196="","",Позиции!C196) -> Изоляция прямоугольных воздуховодов | C21: =IF(Позиции!D196="","",Позиции!D196) -> м2 | D21: =IF(Позиции!L196="","",Позиции!L196) -> 120 | E21: =IF(Позиции!O196="","",Позиции!O196) -> 665.89 | F21: =IF(Позиции!P196="","",Позиции!P196) -> ДС п.1.33 (K-Flex, м²) | G21: =IF(Позиции!M196="","",Позиции!M196) -> 665 | H21: =IF(Позиции!Q196="","",Позиции!Q196) -> -0.89 | I21: =IF(Позиции!R196="","",Позиции!R196) -> -106.8 | J21: =IF(Позиции!T196="","",Позиции!T196) -> Новая работа: НИЖЕ цены аналога из ДС | K21: =IF(Позиции!U196="","",Позиции!U196)
B22: ИТОГО | I22: =SUM(I4:I21) -> -1569975
B23: Красным — позиции подписанного ДС №1; без заливки — новые работы, где цена ниже такого же изделия в ДС.

Sheet Позиции
A1: Наше КП (22,67 млн) · правки заказчика (16,07 млн) · подписанные Договор и ДС №1
A2: Разделы 1–2 (3, 7–9 этажи) — работы по ДС №1 от 27.07.2026, цены подписаны. Разделы 3–7 — новые работы, цен в договоре нет; сравнение с ценой аналога из ДС/договора. Суммы без НДС (Подрядчик на УСН).
E3: ДС №1 от 27.07.2026 (подписано) | H3: Договор 19.06 | I3: Наше КП | L3: Заказчик (с учётом всех правок) | O3: Сравнение | V3: Наша позиция по письму
A4: Раздел | B4: № | C4: Наименование | D4: Ед. | E4: Кол-во | F4: Цена, ₽ | G4: Сумма, ₽ | H4: Цена в Прил.1 к Договору, ₽ | I4: Кол-во | J4: Цена, ₽ | K4: Сумма, ₽ | L4: Кол-во | M4: Цена, ₽ | N4: Сумма, ₽ | O4: Цена-ориентир (ДС или аналог), ₽ | P4: Откуда ориентир | Q4: Заказчик против ориентира, ₽ за ед. | R4: Заказчик против ориентира, ₽ на объём | S4: Заказчик против нашего КП, ₽ | T4: Вывод | U4: Комментарий | V4: Раздел письма | W4: Кол-во | X4: Цена, ₽ | Y4: Сумма, ₽
B5: 1. Вентиляция — работы по ДС №1
A6: 1. Вентиляция | B6: 1.1 | C6: Диффузор 160 мм | D6: шт | E6: 4 | F6: 600 | G6: =IF(E6="","",E6*F6) -> 2400 | H6: 600 | I6: 72 | J6: 600 | K6: =I6*J6 -> 43200 | L6: 72 | M6: 600 | N6: =L6*M6 -> 43200 | O6: 600 | P6: ДС №1 п.1.1 | Q6: =IF(OR(O6="",M6=""),"",M6-O6) -> 0 | R6: =IF(Q6="","",Q6*L6) -> 0 | S6: =N6-K6 -> 0 | T6: Цена ДС №1 — без изменений | W6: =L6 -> 72 | X6: =M6 -> 600 | Y6: =IF(OR(W6="",X6=""),0,W6*X6) -> 43200
A7: 1. Вентиляция | B7: 1.2 | C7: Диффузор 160 мм (сущ) исключено | D7: шт | E7: 16 | F7: 600 | G7: =IF(E7="","",E7*F7) -> 9600 | I7: 0 | J7: 0 | K7: =I7*J7 -> 0 | L7: 0 | N7: =L7*M7 -> 0 | O7: 600 | P7: ДС №1 п.1.2 | Q7: =IF(OR(O7="",M7=""),"",M7-O7) | R7: =IF(Q7="","",Q7*L7) | S7: =N7-K7 -> 0 | T7: Исключено нами (в ДС есть) | U7: В ДС №1: 16 × 600.00 ₽. Мы сами пометили «исключено» — проверить выполнялась ли работа. | W7: =L7 -> 0 | X7: =M7 -> 0 | Y7: =IF(OR(W7="",X7=""),0,W7*X7) -> 0
A8: 1. Вентиляция | B8: 1.3 | C8: Диффузор 100 мм | D8: шт | E8: 12 | F8: 600 | G8: =IF(E8="","",E8*F8) -> 7200 | I8: 8 | J8: 600 | K8: =I8*J8 -> 4800 | L8: 8 | M8: 600 | N8: =L8*M8 -> 4800 | O8: 600 | P8: ДС №1 п.1.3 | Q8: =IF(OR(O8="",M8=""),"",M8-O8) -> 0 | R8: =IF(Q8="","",Q8*L8) -> 0 | S8: =N8-K8 -> 0 | T8: Цена ДС №1 — без изменений | W8: =L8 -> 8 | X8: =M8 -> 600 | Y8: =IF(OR(W8="",X8=""),0,W8*X8) -> 4800
A9: 1. Вентиляция | B9: 1.4 | C9: Решетка щелевая SWANa 2-1200 (сущ) исключено | D9: шт | E9: 8 | F9: 4000 | G9: =IF(E9="","",E9*F9) -> 32000 | I9: 0 | J9: 0 | K9: =I9*J9 -> 0 | L9: 0 | N9: =L9*M9 -> 0 | O9: 4000 | P9: ДС №1 п.1.4 | Q9: =IF(OR(O9="",M9=""),"",M9-O9) | R9: =IF(Q9="","",Q9*L9) | S9: =N9-K9 -> 0 | T9: Исключено нами (в ДС есть) | U9: В ДС №1: 8 × 4 000.00 ₽. Мы сами пометили «исключено» — проверить выполнялась ли работа. | W9: =L9 -> 0 | X9: =M9 -> 0 | Y9: =IF(OR(W9="",X9=""),0,W9*X9) -> 0
A10: 1. Вентиляция | B10: 1.5 | C10: Регулятор расхода воздуха, Ø100 | D10: шт | E10: 12 | F10: 950 | G10: =IF(E10="","",E10*F10) -> 11400 | I10: 12 | J10: 950 | K10: =I10*J10 -> 11400 | L10: 12 | M10: 950 | N10: =L10*M10 -> 11400 | O10: 950 | P10: ДС №1 п.1.5 | Q10: =IF(OR(O10="",M10=""),"",M10-O10) -> 0 | R10: =IF(Q10="","",Q10*L10) -> 0 | S10: =N10-K10 -> 0 | T10: Цена ДС №1 — без изменений | W10: =L10 -> 12 | X10: =M10 -> 950 | Y10: =IF(OR(W10="",X10=""),0,W10*X10) -> 11400
A11: 1. Вентиляция | B11: 1.6 | C11: Регулятор расхода воздуха, Ø160 | D11: шт | E11: 36 | F11: 950 | G11: =IF(E11="","",E11*F11) -> 34200 | I11: 60 | J11: 950 | K11: =I11*J11 -> 57000 | L11: 60 | M11: 950 | N11: =L11*M11 -> 57000 | O11: 950 | P11: ДС №1 п.1.6 | Q11: =IF(OR(O11="",M11=""),"",M11-O11) -> 0 | R11: =IF(Q11="","",Q11*L11) -> 0 | S11: =N11-K11 -> 0 | T11: Цена ДС №1 — без изменений | W11: =L11 -> 60 | X11: =M11 -> 950 | Y11: =IF(OR(W11="",X11=""),0,W11*X11) -> 57000
A12: 1. Вентиляция | B12: 1.7 | C12: Регулятор расхода воздуха, Ø200 | D12: шт | E12: 88 | F12: 950 | G12: =IF(E12="","",E12*F12) -> 83600 | I12: 64 | J12: 950 | K12: =I12*J12 -> 60800 | L12: 64 | M12: 950 | N12: =L12*M12 -> 60800 | O12: 950 | P12: ДС №1 п.1.7 | Q12: =IF(OR(O12="",M12=""),"",M12-O12) -> 0 | R12: =IF(Q12="","",Q12*L12) -> 0 | S12: =N12-K12 -> 0 | T12: Цена ДС №1 — без изменений | W12: =L12 -> 64 | X12: =M12 -> 950 | Y12: =IF(OR(W12="",X12=""),0,W12*X12) -> 60800
A13: 1. Вентиляция | B13: 1.8 | C13: Регулятор расхода воздуха, Ø250 | D13: шт | E13: 4 | F13: 950 | G13: =IF(E13="","",E13*F13) -> 3800 | I13: 8 | J13: 950 | K13: =I13*J13 -> 7600 | L13: 8 | M13: 950 | N13: =L13*M13 -> 7600 | O13: 950 | P13: ДС №1 п.1.8 | Q13: =IF(OR(O13="",M13=""),"",M13-O13) -> 0 | R13: =IF(Q13="","",Q13*L13) -> 0 | S13: =N13-K13 -> 0 | T13: Цена ДС №1 — без изменений | W13: =L13 -> 8 | X13: =M13 -> 950 | Y13: =IF(OR(W13="",X13=""),0,W13*X13) -> 7600
A14: 1. Вентиляция | B14: 1.9 | C14: Воздуховод гофрированный 160 исключено | D14: м | E14: 40 | F14: 474.36 | G14: =IF(E14="","",E14*F14) -> 18974.4 | H14: 474.36 | I14: 0 | J14: 0 | K14: =I14*J14 -> 0 | L14: 0 | N14: =L14*M14 -> 0 | O14: 474.36 | P14: ДС №1 п.1.9 | Q14: =IF(OR(O14="",M14=""),"",M14-O14) | R14: =IF(Q14="","",Q14*L14) | S14: =N14-K14 -> 0 | T14: Исключено нами (в ДС есть) | U14: В ДС №1: 40 × 474.36 ₽. Мы сами пометили «исключено» — проверить выполнялась ли работа. | W14: =L14 -> 0 | X14: =M14 -> 0 | Y14: =IF(OR(W14="",X14=""),0,W14*X14) -> 0
A15: 1. Вентиляция | B15: 1.10 | C15: Воздуховод гофрированный 100 | D15: м | E15: 8 | F15: 760 | G15: =IF(E15="","",E15*F15) -> 6080 | I15: 13.5 | J15: 760 | K15: =I15*J15 -> 10260 | L15: 13.5 | M15: 760 | N15: =L15*M15 -> 10260 | O15: 760 | P15: ДС №1 п.1.10 | Q15: =IF(OR(O15="",M15=""),"",M15-O15) -> 0 | R15: =IF(Q15="","",Q15*L15) -> 0 | S15: =N15-K15 -> 0 | T15: Цена ДС №1 — без изменений | W15: =L15 -> 13.5 | X15: =M15 -> 760 | Y15: =IF(OR(W15="",X15=""),0,W15*X15) -> 10260
A16: 1. Вентиляция | B16: 1.11 | C16: Воздуховод гофрированный Ø160 алюдек | D16: м | E16: 48 | F16: 760 | G16: =IF(E16="","",E16*F16) -> 36480 | I16: 26.5 | J16: 760 | K16: =I16*J16 -> 20140 | L16: 26.5 | M16: 760 | N16: =L16*M16 -> 20140 | O16: 760 | P16: ДС №1 п.1.11 | Q16: =IF(OR(O16="",M16=""),"",M16-O16) -> 0 | R16: =IF(Q16="","",Q16*L16) -> 0 | S16: =N16-K16 -> 0 | T16: Цена ДС №1 — без изменений | W16: =L16 -> 26.5 | X16: =M16 -> 760 | Y16: =IF(OR(W16="",X16=""),0,W16*X16) -> 20140
A17: 1. Вентиляция | B17: 1.12 | C17: Воздуховод гофрированный изолированный, Ø160 санодек | D17: м | E17: 344 | F17: 760 | G17: =IF(E17="","",E17*F17) -> 261440 | I17: 50 | J17: 760 | K17: =I17*J17 -> 38000 | L17: 50 | M17: 760 | N17: =L17*M17 -> 38000 | O17: 760 | P17: ДС №1 п.1.12 | Q17: =IF(OR(O17="",M17=""),"",M17-O17) -> 0 | R17: =IF(Q17="","",Q17*L17) -> 0 | S17: =N17-K17 -> 0 | T17: Цена ДС №1 — без изменений | W17: =L17 -> 50 | X17: =M17 -> 760 | Y17: =IF(OR(W17="",X17=""),0,W17*X17) -> 38000
A18: 1. Вентиляция | B18: 1.13 | C18: Воздуховод(класс герм. "В") толщина лист. стали b-0,5мм 100 - | D18: м | E18: 20 | F18: 950 | G18: =IF(E18="","",E18*F18) -> 19000 | I18: 5.2 | J18: 950 | K18: =I18*J18 -> 4940 | L18: 5.2 | M18: 950 | N18: =L18*M18 -> 4940 | O18: 950 | P18: ДС №1 п.1.13 | Q18: =IF(OR(O18="",M18=""),"",M18-O18) -> 0 | R18: =IF(Q18="","",Q18*L18) -> 0 | S18: =N18-K18 -> 0 | T18: Цена ДС №1 — без изменений | W18: =L18 -> 5.2 | X18: =M18 -> 950 | Y18: =IF(OR(W18="",X18=""),0,W18*X18) -> 4940
A19: 1. Вентиляция | B19: 1.14 | C19: Воздуховод(класс герм. "В") толщина лист. стали b-0,5мм 160 | D19: м | E19: 760 | F19: 689.79 | G19: =IF(E19="","",E19*F19) -> 524240.4 | H19: 689.79 | I19: 771.3 | J19: 689.79 | K19: =I19*J19 -> 532035.03 | L19: 771.3 | M19: 689.79 | N19: =L19*M19 -> 532035.03 | O19: 689.79 | P19: ДС №1 п.1.14 | Q19: =IF(OR(O19="",M19=""),"",M19-O19) -> 0 | R19: =IF(Q19="","",Q19*L19) -> 0 | S19: =N19-K19 -> 0 | T19: Цена ДС №1 — без изменений | W19: =L19 -> 771.3 | X19: =M19 -> 689.79 | Y19: =IF(OR(W19="",X19=""),0,W19*X19) -> 532035.03
A20: 1. Вентиляция | B20: 1.15 | C20: Воздуховод(класс герм. "В") толщина лист. стали b-0,5мм 200 | D20: м | E20: 400 | F20: 862.23 | G20: =IF(E20="","",E20*F20) -> 344892 | H20: 862.23 | I20: 204.6 | J20: 862.23 | K20: =I20*J20 -> 176412.26 | L20: 204.6 | M20: 862.23 | N20: =L20*M20 -> 176412.26 | O20: 862.23 | P20: ДС №1 п.1.15 | Q20: =IF(OR(O20="",M20=""),"",M20-O20) -> 0 | R20: =IF(Q20="","",Q20*L20) -> 0 | S20: =N20-K20 -> 0 | T20: Цена ДС №1 — без изменений | W20: =L20 -> 204.6 | X20: =M20 -> 862.23 | Y20: =IF(OR(W20="",X20=""),0,W20*X20) -> 176412.26
A21: 1. Вентиляция | B21: 1.16 | C21: Воздуховод(класс герм. "В") толщина лист. стали b-0,6мм 250 | D21: м | E21: 12 | F21: 1077.79 | G21: =IF(E21="","",E21*F21) -> 12933.48 | H21: 1077.79 | I21: 4.4 | J21: 1077.79 | K21: =I21*J21 -> 4742.276 | L21: 4.4 | M21: 1077.79 | N21: =L21*M21 -> 4742.276 | O21: 1077.79 | P21: ДС №1 п.1.16 | Q21: =IF(OR(O21="",M21=""),"",M21-O21) -> 0 | R21: =IF(Q21="","",Q21*L21) -> 0 | S21: =N21-K21 -> 0 | T21: Цена ДС №1 — без изменений | W21: =L21 -> 4.4 | X21: =M21 -> 1077.79 | Y21: =IF(OR(W21="",X21=""),0,W21*X21) -> 4742.276
A22: 1. Вентиляция | B22: 1.17 | C22: Тройник ф 160 | D22: шт. | E22: 80 | F22: 855 | G22: =IF(E22="","",E22*F22) -> 68400 | I22: 155 | J22: 855 | K22: =I22*J22 -> 132525 | L22: 155 | M22: 855 | N22: =L22*M22 -> 132525 | O22: 855 | P22: ДС №1 п.1.17 | Q22: =IF(OR(O22="",M22=""),"",M22-O22) -> 0 | R22: =IF(Q22="","",Q22*L22) -> 0 | S22: =N22-K22 -> 0 | T22: Цена ДС №1 — без изменений | W22: =L22 -> 155 | X22: =M22 -> 855 | Y22: =IF(OR(W22="",X22=""),0,W22*X22) -> 132525
A23: 1. Вентиляция | B23: 1.18 | C23: Тройник ф 200 | D23: шт. | E23: 8 | F23: 855 | G23: =IF(E23="","",E23*F23) -> 6840 | I23: 7 | J23: 855 | K23: =I23*J23 -> 5985 | L23: 7 | M23: 855 | N23: =L23*M23 -> 5985 | O23: 855 | P23: ДС №1 п.1.18 | Q23: =IF(OR(O23="",M23=""),"",M23-O23) -> 0 | R23: =IF(Q23="","",Q23*L23) -> 0 | S23: =N23-K23 -> 0 | T23: Цена ДС №1 — без изменений | W23: =L23 -> 7 | X23: =M23 -> 855 | Y23: =IF(OR(W23="",X23=""),0,W23*X23) -> 5985
A24: 1. Вентиляция | B24: 1.19 | C24: Переход 160-200 | D24: шт. | E24: 100 | F24: 855 | G24: =IF(E24="","",E24*F24) -> 85500 | I24: 104 | J24: 855 | K24: =I24*J24 -> 88920 | L24: 104 | M24: 855 | N24: =L24*M24 -> 88920 | O24: 855 | P24: ДС №1 п.1.19 | Q24: =IF(OR(O24="",M24=""),"",M24-O24) -> 0 | R24: =IF(Q24="","",Q24*L24) -> 0 | S24: =N24-K24 -> 0 | T24: Цена ДС №1 — без изменений | W24: =L24 -> 104 | X24: =M24 -> 855 | Y24: =IF(OR(W24="",X24=""),0,W24*X24) -> 88920
A25: 1. Вентиляция | B25: 1.20 | C25: Отвод 90 ф160 | D25: шт. | E25: 92 | F25: 855 | G25: =IF(E25="","",E25*F25) -> 78660 | I25: 272 | J25: 855 | K25: =I25*J25 -> 232560 | L25: 272 | M25: 855 | N25: =L25*M25 -> 232560 | O25: 855 | P25: ДС №1 п.1.20 | Q25: =IF(OR(O25="",M25=""),"",M25-O25) -> 0 | R25: =IF(Q25="","",Q25*L25) -> 0 | S25: =N25-K25 -> 0 | T25: Цена ДС №1 — без изменений | W25: =L25 -> 272 | X25: =M25 -> 855 | Y25: =IF(OR(W25="",X25=""),0,W25*X25) -> 232560
A26: 1. Вентиляция | B26: 1.21 | C26: Отвод 45 Ф160 | D26: шт. | E26: 92 | F26: 855 | G26: =IF(E26="","",E26*F26) -> 78660 | I26: 243 | J26: 855 | K26: =I26*J26 -> 207765 | L26: 243 | M26: 855 | N26: =L26*M26 -> 207765 | O26: 855 | P26: ДС №1 п.1.21 | Q26: =IF(OR(O26="",M26=""),"",M26-O26) -> 0 | R26: =IF(Q26="","",Q26*L26) -> 0 | S26: =N26-K26 -> 0 | T26: Цена ДС №1 — без изменений | W26: =L26 -> 243 | X26: =M26 -> 855 | Y26: =IF(OR(W26="",X26=""),0,W26*X26) -> 207765
A27: 1. Вентиляция | B27: 1.22 | C27: Тройник 200/160/200 исключено | D27: шт. | E27: 108 | F27: 855 | G27: =IF(E27="","",E27*F27) -> 92340 | I27: 0 | J27: 0 | K27: =I27*J27 -> 0 | L27: 0 | N27: =L27*M27 -> 0 | O27: 855 | P27: ДС №1 п.1.22 | Q27: =IF(OR(O27="",M27=""),"",M27-O27) | R27: =IF(Q27="","",Q27*L27) | S27: =N27-K27 -> 0 | T27: Исключено нами (в ДС есть) | U27: В ДС №1: 108 × 855.00 ₽. Мы сами пометили «исключено» — проверить выполнялась ли работа. | W27: =L27 -> 0 | X27: =M27 -> 0 | Y27: =IF(OR(W27="",X27=""),0,W27*X27) -> 0
A28: 1. Вентиляция | B28: 1.23 | C28: КВК ф250 исключено | D28: шт. | E28: 4 | F28: 950 | G28: =IF(E28="","",E28*F28) -> 3800 | I28: 0 | J28: 0 | K28: =I28*J28 -> 0 | L28: 0 | N28: =L28*M28 -> 0 | O28: 950 | P28: ДС №1 п.1.23 | Q28: =IF(OR(O28="",M28=""),"",M28-O28) | R28: =IF(Q28="","",Q28*L28) | S28: =N28-K28 -> 0 | T28: Исключено нами (в ДС есть) | U28: В ДС №1: 4 × 950.00 ₽. Мы сами пометили «исключено» — проверить выполнялась ли работа. | W28: =L28 -> 0 | X28: =M28 -> 0 | Y28: =IF(OR(W28="",X28=""),0,W28*X28) -> 0
A29: 1. Вентиляция | B29: 1.24 | C29: Переход с воздуховодов на врезку балки | D29: шт. | E29: 340 | F29: 950 | G29: =IF(E29="","",E29*F29) -> 323000 | I29: 340 | J29: 950 | K29: =I29*J29 -> 323000 | L29: 340 | M29: 950 | N29: =L29*M29 -> 323000 | O29: 950 | P29: ДС №1 п.1.24 | Q29: =IF(OR(O29="",M29=""),"",M29-O29) -> 0 | R29: =IF(Q29="","",Q29*L29) -> 0 | S29: =N29-K29 -> 0 | T29: Цена ДС №1 — без изменений | W29: =L29 -> 340 | X29: =M29 -> 950 | Y29: =IF(OR(W29="",X29=""),0,W29*X29) -> 323000
A30: 1. Вентиляция | B30: 1.25 | C30: Отвод 90 ф200 | D30: шт. | E30: 76 | F30: 855 | G30: =IF(E30="","",E30*F30) -> 64980 | I30: 32 | J30: 855 | K30: =I30*J30 -> 27360 | L30: 32 | M30: 855 | N30: =L30*M30 -> 27360 | O30: 855 | P30: ДС №1 п.1.25 | Q30: =IF(OR(O30="",M30=""),"",M30-O30) -> 0 | R30: =IF(Q30="","",Q30*L30) -> 0 | S30: =N30-K30 -> 0 | T30: Цена ДС №1 — без изменений | W30: =L30 -> 32 | X30: =M30 -> 855 | Y30: =IF(OR(W30="",X30=""),0,W30*X30) -> 27360
A31: 1. Вентиляция | B31: 1.26 | C31: Отвод 45 ф 200 | D31: шт. | E31: 88 | F31: 855 | G31: =IF(E31="","",E31*F31) -> 75240 | I31: 113 | J31: 855 | K31: =I31*J31 -> 96615 | L31: 113 | M31: 855 | N31: =L31*M31 -> 96615 | O31: 855 | P31: ДС №1 п.1.26 | Q31: =IF(OR(O31="",M31=""),"",M31-O31) -> 0 | R31: =IF(Q31="","",Q31*L31) -> 0 | S31: =N31-K31 -> 0 | T31: Цена ДС №1 — без изменений | W31: =L31 -> 113 | X31: =M31 -> 855 | Y31: =IF(OR(W31="",X31=""),0,W31*X31) -> 96615
A32: 1. Вентиляция | B32: 1.27 | C32: КВК ф 200 исключено | D32: шт. | E32: 88 | F32: 950 | G32: =IF(E32="","",E32*F32) -> 83600 | I32: 0 | J32: 0 | K32: =I32*J32 -> 0 | L32: 0 | N32: =L32*M32 -> 0 | O32: 950 | P32: ДС №1 п.1.27 | Q32: =IF(OR(O32="",M32=""),"",M32-O32) | R32: =IF(Q32="","",Q32*L32) | S32: =N32-K32 -> 0 | T32: Исключено нами (в ДС есть) | U32: В ДС №1: 88 × 950.00 ₽. Мы сами пометили «исключено» — проверить выполнялась ли работа. | W32: =L32 -> 0 | X32: =M32 -> 0 | Y32: =IF(OR(W32="",X32=""),0,W32*X32) -> 0
A33: 1. Вентиляция | B33: 1.28 | C33: КВК160 исключено | D33: шт. | E33: 24 | F33: 950 | G33: =IF(E33="","",E33*F33) -> 22800 | I33: 0 | J33: 0 | K33: =I33*J33 -> 0 | L33: 0 | N33: =L33*M33 -> 0 | O33: 950 | P33: ДС №1 п.1.28 | Q33: =IF(OR(O33="",M33=""),"",M33-O33) | R33: =IF(Q33="","",Q33*L33) | S33: =N33-K33 -> 0 | T33: Исключено нами (в ДС есть) | U33: В ДС №1: 24 × 950.00 ₽. Мы сами пометили «исключено» — проверить выполнялась ли работа. | W33: =L33 -> 0 | X33: =M33 -> 0 | Y33: =IF(OR(W33="",X33=""),0,W33*X33) -> 0
A34: 1. Вентиляция | B34: 1.29 | C34: Отвод 90 ф100 | D34: шт. | E34: 4 | F34: 855 | G34: =IF(E34="","",E34*F34) -> 3420 | I34: 2 | J34: 855 | K34: =I34*J34 -> 1710 | L34: 2 | M34: 855 | N34: =L34*M34 -> 1710 | O34: 855 | P34: ДС №1 п.1.29 | Q34: =IF(OR(O34="",M34=""),"",M34-O34) -> 0 | R34: =IF(Q34="","",Q34*L34) -> 0 | S34: =N34-K34 -> 0 | T34: Цена ДС №1 — без изменений | W34: =L34 -> 2 | X34: =M34 -> 855 | Y34: =IF(OR(W34="",X34=""),0,W34*X34) -> 1710
A35: 1. Вентиляция | B35: 1.30 | C35: Переход 250\200 | D35: шт. | E35: 4 | F35: 855 | G35: =IF(E35="","",E35*F35) -> 3420 | I35: 10 | J35: 855 | K35: =I35*J35 -> 8550 | L35: 10 | M35: 855 | N35: =L35*M35 -> 8550 | O35: 855 | P35: ДС №1 п.1.30 | Q35: =IF(OR(O35="",M35=""),"",M35-O35) -> 0 | R35: =IF(Q35="","",Q35*L35) -> 0 | S35: =N35-K35 -> 0 | T35: Цена ДС №1 — без изменений | W35: =L35 -> 10 | X35: =M35 -> 855 | Y35: =IF(OR(W35="",X35=""),0,W35*X35) -> 8550
A36: 1. Вентиляция | B36: 1.31 | C36: КВК ф100 исключено | D36: шт. | E36: 4 | F36: 950 | G36: =IF(E36="","",E36*F36) -> 3800 | I36: 0 | J36: 0 | K36: =I36*J36 -> 0 | L36: 0 | N36: =L36*M36 -> 0 | O36: 950 | P36: ДС №1 п.1.31 | Q36: =IF(OR(O36="",M36=""),"",M36-O36) | R36: =IF(Q36="","",Q36*L36) | S36: =N36-K36 -> 0 | T36: Исключено нами (в ДС есть) | U36: В ДС №1: 4 × 950.00 ₽. Мы сами пометили «исключено» — проверить выполнялась ли работа. | W36: =L36 -> 0 | X36: =M36 -> 0 | Y36: =IF(OR(W36="",X36=""),0,W36*X36) -> 0
A37: 1. Вентиляция | B37: 1.32 | C37: Проделка отверстий | D37: шт. | E37: 120 | F37: 570 | G37: =IF(E37="","",E37*F37) -> 68400 | I37: 128 | J37: 570 | K37: =I37*J37 -> 72960 | L37: 128 | M37: 570 | N37: =L37*M37 -> 72960 | O37: 570 | P37: ДС №1 п.1.32 | Q37: =IF(OR(O37="",M37=""),"",M37-O37) -> 0 | R37: =IF(Q37="","",Q37*L37) -> 0 | S37: =N37-K37 -> 0 | T37: Цена ДС №1 — без изменений | W37: =L37 -> 128 | X37: =M37 -> 570 | Y37: =IF(OR(W37="",X37=""),0,W37*X37) -> 72960
A38: 1. Вентиляция | B38: 1.33 | C38: Универсальная теплоизоляция в виде рулонов, толщиной 6 мм K- Flex-ST | D38: м2 | E38: 800 | F38: 665.89 | G38: =IF(E38="","",E38*F38) -> 532712 | H38: 665.89 | I38: 882 | J38: 665.89 | K38: =I38*J38 -> 587314.98 | L38: 882 | M38: 570 | N38: =L38*M38 -> 502740 | O38: 665.89 | P38: ДС №1 п.1.33 | Q38: =IF(OR(O38="",M38=""),"",M38-O38) -> -95.89 | R38: =IF(Q38="","",Q38*L38) -> -84574.98 | S38: =N38-K38 -> -84574.98 | T38: НИЖЕ подписанной цены ДС №1 | U38: Заказчик: р по договору | V38: 1 | W38: 882 | X38: 665.89 | Y38: =IF(OR(W38="",X38=""),0,W38*X38) -> 587314.98
A39: 1. Вентиляция | B39: 1.34 | C39: ПНР 3-10 эт | D39: комп | E39: 5 | F39: 95238.1 | G39: =IF(E39="","",E39*F39) -> 476190.5 | H39: 95238.1 | I39: 4 | J39: 95238.1 | K39: =I39*J39 -> 380952.4 | L39: 4 | M39: 95238.1 | N39: =L39*M39 -> 380952.4 | O39: 95238.1 | P39: ДС №1 п.1.34 | Q39: =IF(OR(O39="",M39=""),"",M39-O39) -> 0 | R39: =IF(Q39="","",Q39*L39) -> 0 | S39: =N39-K39 -> 0 | T39: Цена ДС №1 — без изменений | W39: =L39 -> 4 | X39: =M39 -> 95238.1 | Y39: =IF(OR(W39="",X39=""),0,W39*X39) -> 380952.4
B40: 2. Кондиционирование — работы по ДС №1
...
