Workbook

Sheet Сводка
A1: Сравнение КП: где и на сколько нам снизили цены
A2: Исходное КП (наше) vs файл с правками заказчика. Все суммы в рублях без НДС; считаются формулами по листу «Все позиции».
A4: Главное
A5: Наше КП (исходное) | B5: =SUM('Все позиции'!$G$5:$G$331) -> 22665254
A6: Итог в файле заказчика (как у них посчитано) | B6: =SUM('Все позиции'!$J$5:$J$331) -> 16526808
A7: Ещё снижения в комментариях, не внесённые в их итог | B7: =SUM('Все позиции'!$M$5:$M$331)-SUM('Все позиции'!$J$5:$J$331) -> -452611.16
A8: Итог с учётом ВСЕХ правок заказчика | B8: =SUM('Все позиции'!$M$5:$M$331) -> 16074197
A9: Общее снижение против нашего КП, ₽ | B9: =B8-B5 -> -6591057
A10: Общее снижение, % | B10: =IF(B5=0,"",B9/B5) -> -0.29080005
A11: По разделам
A12: Раздел | B12: Наше КП, ₽ | C12: В файле заказчика, ₽ | D12: С учётом всех правок, ₽ | E12: Разница, ₽ | F12: Разница, %
A13: 1. Вентиляция | B13: =SUMIFS('Все позиции'!$G$5:$G$331,'Все позиции'!$A$5:$A$331,$A13) -> 3137546.9 | C13: =SUMIFS('Все позиции'!$J$5:$J$331,'Все позиции'!$A$5:$A$331,$A13) -> 3137546.9 | D13: =SUMIFS('Все позиции'!$M$5:$M$331,'Все позиции'!$A$5:$A$331,$A13) -> 3052972 | E13: =D13-B13 -> -84574.98 | F13: =IF(B13=0,"",E13/B13) -> -0.026955766
A14: 2. Кондиционирование | B14: =SUMIFS('Все позиции'!$G$5:$G$331,'Все позиции'!$A$5:$A$331,$A14) -> 9902752 | C14: =SUMIFS('Все позиции'!$J$5:$J$331,'Все позиции'!$A$5:$A$331,$A14) -> 8491752 | D14: =SUMIFS('Все позиции'!$M$5:$M$331,'Все позиции'!$A$5:$A$331,$A14) -> 8179752 | E14: =D14-B14 -> -1723000 | F14: =IF(B14=0,"",E14/B14) -> -0.17399204
A15: 3. Дополнительные работы 3,7,8,9 этаж | B15: =SUMIFS('Все позиции'!$G$5:$G$331,'Все позиции'!$A$5:$A$331,$A15) -> 1951684 | C15: =SUMIFS('Все позиции'!$J$5:$J$331,'Все позиции'!$A$5:$A$331,$A15) -> 1411914 | D15: =SUMIFS('Все позиции'!$M$5:$M$331,'Все позиции'!$A$5:$A$331,$A15) -> 1411914 | E15: =D15-B15 -> -539770 | F15: =IF(B15=0,"",E15/B15) -> -0.27656629
A16: 4. Вентиляция 10 этаж | B16: =SUMIFS('Все позиции'!$G$5:$G$331,'Все позиции'!$A$5:$A$331,$A16) -> 1416664.8 | C16: =SUMIFS('Все позиции'!$J$5:$J$331,'Все позиции'!$A$5:$A$331,$A16) -> 845451.58 | D16: =SUMIFS('Все позиции'!$M$5:$M$331,'Все позиции'!$A$5:$A$331,$A16) -> 845451.58 | E16: =D16-B16 -> -571213.22 | F16: =IF(B16=0,"",E16/B16) -> -0.40320986
A17: 4. Дымоудаление (10 этаж) | B17: =SUMIFS('Все позиции'!$G$5:$G$331,'Все позиции'!$A$5:$A$331,$A17) -> 253760 | C17: =SUMIFS('Все позиции'!$J$5:$J$331,'Все позиции'!$A$5:$A$331,$A17) -> 0 | D17: =SUMIFS('Все позиции'!$M$5:$M$331,'Все позиции'!$A$5:$A$331,$A17) -> 0 | E17: =D17-B17 -> -253760 | F17: =IF(B17=0,"",E17/B17) -> -1
A18: 5. Холодоснабжение 10 этаж | B18: =SUMIFS('Все позиции'!$G$5:$G$331,'Все позиции'!$A$5:$A$331,$A18) -> 1777290 | C18: =SUMIFS('Все позиции'!$J$5:$J$331,'Все позиции'!$A$5:$A$331,$A18) -> 1075964 | D18: =SUMIFS('Все позиции'!$M$5:$M$331,'Все позиции'!$A$5:$A$331,$A18) -> 1075964 | E18: =D18-B18 -> -701326 | F18: =IF(B18=0,"",E18/B18) -> -0.39460414
A19: 6. Вентиляция 2 этаж | B19: =SUMIFS('Все позиции'!$G$5:$G$331,'Все позиции'!$A$5:$A$331,$A19) -> 1563350.4 | C19: =SUMIFS('Все позиции'!$J$5:$J$331,'Все позиции'!$A$5:$A$331,$A19) -> 863491.78 | D19: =SUMIFS('Все позиции'!$M$5:$M$331,'Все позиции'!$A$5:$A$331,$A19) -> 815195.6 | E19: =D19-B19 -> -748154.8 | F19: =IF(B19=0,"",E19/B19) -> -0.47855861
A20: 6. Дымоудаление (2 этаж) | B20: =SUMIFS('Все позиции'!$G$5:$G$331,'Все позиции'!$A$5:$A$331,$A20) -> 774720 | C20: =SUMIFS('Все позиции'!$J$5:$J$331,'Все позиции'!$A$5:$A$331,$A20) -> 0 | D20: =SUMIFS('Все позиции'!$M$5:$M$331,'Все позиции'!$A$5:$A$331,$A20) -> 0 | E20: =D20-B20 -> -774720 | F20: =IF(B20=0,"",E20/B20) -> -1
A21: 7. Холодоснабжение 2 этаж | B21: =SUMIFS('Все позиции'!$G$5:$G$331,'Все позиции'!$A$5:$A$331,$A21) -> 1887486 | C21: =SUMIFS('Все позиции'!$J$5:$J$331,'Все позиции'!$A$5:$A$331,$A21) -> 700688 | D21: =SUMIFS('Все позиции'!$M$5:$M$331,'Все позиции'!$A$5:$A$331,$A21) -> 692948 | E21: =D21-B21 -> -1194538 | F21: =IF(B21=0,"",E21/B21) -> -0.63287251
A22: ИТОГО | B22: =SUM(B13:B21) -> 22665254 | C22: =SUM(C13:C21) -> 16526808 | D22: =SUM(D13:D21) -> 16074197 | E22: =SUM(E13:E21) -> -6591057 | F22: =IF(B22=0,"",E22/B22) -> -0.29080005
A24: Из-за чего снижение
A25: Что произошло | B25: Позиций | C25: Разница, ₽ | D25: Доля в общем снижении
A26: Цена снижена | B26: =COUNTIF('Все позиции'!$P$5:$P$331,A26) -> 175 | C26: =SUMIFS('Все позиции'!$N$5:$N$331,'Все позиции'!$P$5:$P$331,A26) -> -3881419.8 | D26: =IF($C$34=0,"",C26/$C$34) -> 0.58889186
A27: Снижены цена и количество | B27: =COUNTIF('Все позиции'!$P$5:$P$331,A27) -> 1 | C27: =SUMIFS('Все позиции'!$N$5:$N$331,'Все позиции'!$P$5:$P$331,A27) -> -78200 | D27: =IF($C$34=0,"",C27/$C$34) -> 0.011864561
A28: Удалено заказчиком без комментария | B28: =COUNTIF('Все позиции'!$P$5:$P$331,A28) -> 6 | C28: =SUMIFS('Все позиции'!$N$5:$N$331,'Все позиции'!$P$5:$P$331,A28) -> -1151370 | D28: =IF($C$34=0,"",C28/$C$34) -> 0.1746867
A29: Исключено → отдельный допник | B29: =COUNTIF('Все позиции'!$P$5:$P$331,A29) -> 8 | C29: =SUMIFS('Все позиции'!$N$5:$N$331,'Все позиции'!$P$5:$P$331,A29) -> -1028480 | D29: =IF($C$34=0,"",C29/$C$34) -> 0.15604174
A30: Снижение согласовано, но не внесено в итог | B30: =COUNTIF('Все позиции'!$P$5:$P$331,A30) -> 6 | C30: =SUMIFS('Все позиции'!$N$5:$N$331,'Все позиции'!$P$5:$P$331,A30) -> -404314.98 | D30: =IF($C$34=0,"",C30/$C$34) -> 0.061342965
A31: Снижение предложено, но не внесено в итог | B31: =COUNTIF('Все позиции'!$P$5:$P$331,A31) -> 3 | C31: =SUMIFS('Все позиции'!$N$5:$N$331,'Все позиции'!$P$5:$P$331,A31) -> -48296.18 | D31: =IF($C$34=0,"",C31/$C$34) -> 0.0073275318
A32: Цена повышена | B32: =COUNTIF('Все позиции'!$P$5:$P$331,A32) -> 3 | C32: =SUMIFS('Все позиции'!$N$5:$N$331,'Все позиции'!$P$5:$P$331,A32) -> 1024 | D32: =IF($C$34=0,"",C32/$C$34) -> -0.00015536203
A33: Без изменений | B33: =COUNTIF('Все позиции'!$P$5:$P$331,A33) -> 117 | C33: =SUMIFS('Все позиции'!$N$5:$N$331,'Все позиции'!$P$5:$P$331,A33) -> 0 | D33: =IF($C$34=0,"",C33/$C$34) -> 0
A34: ИТОГО | B34: =SUM(B26:B33) -> 319 | C34: =SUM(C26:C33) -> -6591057 | D34: =IF(C34=0,"",C34/C34) -> 1
A35: Проверка: итог по причинам = итогу по разделам → | C35: =IF(ABS(C34-E22)<0.01,"сходится","НЕ СХОДИТСЯ") -> сходится

Sheet Где занизили
A1: Позиции с изменениями — от самых больших потерь к меньшим
A2: Значения подтягиваются формулами с листа «Все позиции».
A3: Раздел | B3: № | C3: Наименование | D3: Ед. | E3: Кол-во наше | F3: Цена наша, ₽ | G3: Кол-во заказчика | H3: Итоговая цена, ₽ | I3: Изменение цены, % | J3: Сумма наша, ₽ | K3: Итоговая сумма, ₽ | L3: Разница, ₽ | M3: Что произошло | N3: Комментарий заказчика | O3: Ответ / согласование
A4: =IF('Все позиции'!A46="","",'Все позиции'!A46) -> 2. Кондиционирование | B4: =IF('Все позиции'!B46="","",'Все позиции'!B46) -> 2.7 | C4: =IF('Все позиции'!C46="","",'Все позиции'!C46) -> Узел регулирования климатической балки 1/2 Modulator ½ | D4: =IF('Все позиции'!D46="","",'Все позиции'!D46) -> шт. | E4: =IF('Все позиции'!E46="","",'Все позиции'!E46) -> 340 | F4: =IF('Все позиции'!F46="","",'Все позиции'!F46) -> 6650 | G4: =IF('Все позиции'!H46="","",'Все позиции'!H46) -> 340 | H4: =IF('Все позиции'!L46="","",'Все позиции'!L46) -> 2500 | I4: =IF('Все позиции'!O46="","",'Все позиции'!O46) -> -0.62406015 | J4: =IF('Все позиции'!G46="","",'Все позиции'!G46) -> 2261000 | K4: =IF('Все позиции'!M46="","",'Все позиции'!M46) -> 850000 | L4: =IF('Все позиции'!N46="","",'Все позиции'!N46) -> -1411000 | M4: =IF('Все позиции'!P46="","",'Все позиции'!P46) -> Цена снижена | N4: =IF('Все позиции'!Q46="","",'Все позиции'!Q46) -> по договоренности | O4: =IF('Все позиции'!R46="","",'Все позиции'!R46)
A5: =IF('Все позиции'!A321="","",'Все позиции'!A321) -> 7. Холодоснабжение 2 этаж | B5: =IF('Все позиции'!B321="","",'Все позиции'!B321) -> 7.1 | C5: =IF('Все позиции'!C321="","",'Все позиции'!C321) -> Фанкойл кассетный, 600x600 SK-12 | D5: =IF('Все позиции'!D321="","",'Все позиции'!D321) -> шт. | E5: =IF('Все позиции'!E321="","",'Все позиции'!E321) -> 31 | F5: =IF('Все позиции'!F321="","",'Все позиции'!F321) -> 29160 | G5: =IF('Все позиции'!H321="","",'Все позиции'!H321) -> 31 | H5: =IF('Все позиции'!L321="","",'Все позиции'!L321) -> 14000 | I5: =IF('Все позиции'!O321="","",'Все позиции'!O321) -> -0.51989026 | J5: =IF('Все позиции'!G321="","",'Все позиции'!G321) -> 903960 | K5: =IF('Все позиции'!M321="","",'Все позиции'!M321) -> 434000 | L5: =IF('Все позиции'!N321="","",'Все позиции'!N321) -> -469960 | M5: =IF('Все позиции'!P321="","",'Все позиции'!P321) -> Цена снижена | N5: =IF('Все позиции'!Q321="","",'Все позиции'!Q321) | O5: =IF('Все позиции'!R321="","",'Все позиции'!R321)
A6: =IF('Все позиции'!A316="","",'Все позиции'!A316) -> 6. Дымоудаление (2 этаж) | B6: =IF('Все позиции'!B316="","",'Все позиции'!B316) -> 6.75 | C6: =IF('Все позиции'!C316="","",'Все позиции'!C316) -> Воздуховод 800*500 | D6: =IF('Все позиции'!D316="","",'Все позиции'!D316) -> м2 | E6: =IF('Все позиции'!E316="","",'Все позиции'!E316) -> 168 | F6: =IF('Все позиции'!F316="","",'Все позиции'!F316) -> 2560 | G6: =IF('Все позиции'!H316="","",'Все позиции'!H316) -> 168 | H6: =IF('Все позиции'!L316="","",'Все позиции'!L316) | I6: =IF('Все позиции'!O316="","",'Все позиции'!O316) -> -1 | J6: =IF('Все позиции'!G316="","",'Все позиции'!G316) -> 430080 | K6: =IF('Все позиции'!M316="","",'Все позиции'!M316) -> 0 | L6: =IF('Все позиции'!N316="","",'Все позиции'!N316) -> -430080 | M6: =IF('Все позиции'!P316="","",'Все позиции'!P316) -> Исключено → отдельный допник | N6: =IF('Все позиции'!Q316="","",'Все позиции'!Q316) -> удалить (если будут данные позиции сделаем отдельный допник) | O6: =IF('Все позиции'!R316="","",'Все позиции'!R316)
A7: =IF('Все позиции'!A311="","",'Все позиции'!A311) -> 6. Вентиляция 2 этаж | B7: =IF('Все позиции'!B311="","",'Все позиции'!B311) -> 6.71 | C7: =IF('Все позиции'!C311="","",'Все позиции'!C311) -> демонтаж воздуховодов | D7: =IF('Все позиции'!D311="","",'Все позиции'!D311) -> к-т | E7: =IF('Все позиции'!E311="","",'Все позиции'!E311) -> 1 | F7: =IF('Все позиции'!F311="","",'Все позиции'!F311) -> 388800 | G7: =IF('Все позиции'!H311="","",'Все позиции'!H311) -> 0 | H7: =IF('Все позиции'!L311="","",'Все позиции'!L311) | I7: =IF('Все позиции'!O311="","",'Все позиции'!O311) -> -1 | J7: =IF('Все позиции'!G311="","",'Все позиции'!G311) -> 388800 | K7: =IF('Все позиции'!M311="","",'Все позиции'!M311) -> 0 | L7: =IF('Все позиции'!N311="","",'Все позиции'!N311) -> -388800 | M7: =IF('Все позиции'!P311="","",'Все позиции'!P311) -> Удалено заказчиком без комментария | N7: =IF('Все позиции'!Q311="","",'Все позиции'!Q311) | O7: =IF('Все позиции'!R311="","",'Все позиции'!R311)
A8: =IF('Все позиции'!A89="","",'Все позиции'!A89) -> 3. Дополнительные работы 3,7,8,9 этаж | B8: =IF('Все позиции'!B89="","",'Все позиции'!B89) -> 3.7 | C8: =IF('Все позиции'!C89="","",'Все позиции'!C89) -> Изоляция изделий (отводы, тройники, переходы, клапана) | D8: =IF('Все позиции'!D89="","",'Все позиции'!D89) -> шт. | E8: =IF('Все позиции'!E89="","",'Все позиции'!E89) -> 1195 | F8: =IF('Все позиции'!F89="","",'Все позиции'!F89) -> 840 | G8: =IF('Все позиции'!H89="","",'Все позиции'!H89) -> 1195 | H8: =IF('Все позиции'!L89="","",'Все позиции'!L89) -> 570 | I8: =IF('Все позиции'!O89="","",'Все позиции'!O89) -> -0.32142857 | J8: =IF('Все позиции'!G89="","",'Все позиции'!G89) -> 1003800 | K8: =IF('Все позиции'!M89="","",'Все позиции'!M89) -> 681150 | L8: =IF('Все позиции'!N89="","",'Все позиции'!N89) -> -322650 | M8: =IF('Все позиции'!P89="","",'Все позиции'!P89) -> Цена снижена | N8: =IF('Все позиции'!Q89="","",'Все позиции'!Q89) | O8: =IF('Все позиции'!R89="","",'Все позиции'!R89)
A9: =IF('Все позиции'!A317="","",'Все позиции'!A317) -> 6. Дымоудаление (2 этаж) | B9: =IF('Все позиции'!B317="","",'Все позиции'!B317) -> 6.76 | C9: =IF('Все позиции'!C317="","",'Все позиции'!C317) -> Изоляция М-БОР | D9: =IF('Все позиции'!D317="","",'Все позиции'!D317) -> м2 | E9: =IF('Все позиции'!E317="","",'Все позиции'!E317) -> 186 | F9: =IF('Все позиции'!F317="","",'Все позиции'!F317) -> 1440 | G9: =IF('Все позиции'!H317="","",'Все позиции'!H317) -> 186 | H9: =IF('Все позиции'!L317="","",'Все позиции'!L317) | I9: =IF('Все позиции'!O317="","",'Все позиции'!O317) -> -1 | J9: =IF('Все позиции'!G317="","",'Все позиции'!G317) -> 267840 | K9: =IF('Все позиции'!M317="","",'Все позиции'!M317) -> 0 | L9: =IF('Все позиции'!N317="","",'Все позиции'!N317) -> -267840 | M9: =IF('Все позиции'!P317="","",'Все позиции'!P317) -> Исключено → отдельный допник | N9: =IF('Все позиции'!Q317="","",'Все позиции'!Q317) -> удалить (если будут данные позиции сделаем отдельный допник) | O9: =IF('Все позиции'!R317="","",'Все позиции'!R317)
A10: =IF('Все позиции'!A328="","",'Все позиции'!A328) -> 7. Холодоснабжение 2 этаж | B10: =IF('Все позиции'!B328="","",'Все позиции'!B328) -> 7.8 | C10: =IF('Все позиции'!C328="","",'Все позиции'!C328) -> дренаж | D10: =IF('Все позиции'!D328="","",'Все позиции'!D328) -> м.п. | E10: =IF('Все позиции'!E328="","",'Все позиции'!E328) -> 200 | F10: =IF('Все позиции'!F328="","",'Все позиции'!F328) -> 1092 | G10: =IF('Все позиции'!H328="","",'Все позиции'!H328) -> 0 | H10: =IF('Все позиции'!L328="","",'Все позиции'!L328) | I10: =IF('Все позиции'!O328="","",'Все позиции'!O328) -> -1 | J10: =IF('Все позиции'!G328="","",'Все позиции'!G328) -> 218400 | K10: =IF('Все позиции'!M328="","",'Все позиции'!M328) -> 0 | L10: =IF('Все позиции'!N328="","",'Все позиции'!N328) -> -218400 | M10: =IF('Все позиции'!P328="","",'Все позиции'!P328) -> Удалено заказчиком без комментария | N10: =IF('Все позиции'!Q328="","",'Все позиции'!Q328) | O10: =IF('Все позиции'!R328="","",'Все позиции'!R328)
A11: =IF('Все позиции'!A194="","",'Все позиции'!A194) -> 4. Вентиляция 10 этаж | B11: =IF('Все позиции'!B194="","",'Все позиции'!B194) -> 4.81 | C11: =IF('Все позиции'!C194="","",'Все позиции'!C194) -> Изоляция прямоугольного изделия | D11: =IF('Все позиции'!D194="","",'Все позиции'!D194) -> шт. | E11: =IF('Все позиции'!E194="","",'Все позиции'!E194) -> 80 | F11: =IF('Все позиции'!F194="","",'Все позиции'!F194) -> 3240 | G11: =IF('Все позиции'!H194="","",'Все позиции'!H194) -> 80 | H11: =IF('Все позиции'!L194="","",'Все позиции'!L194) -> 665 | I11: =IF('Все позиции'!O194="","",'Все позиции'!O194) -> -0.79475309 | J11: =IF('Все позиции'!G194="","",'Все позиции'!G194) -> 259200 | K11: =IF('Все позиции'!M194="","",'Все позиции'!M194) -> 53200 | L11: =IF('Все позиции'!N194="","",'Все позиции'!N194) -> -206000 | M11: =IF('Все позиции'!P194="","",'Все позиции'!P194) -> Цена снижена | N11: =IF('Все позиции'!Q194="","",'Все позиции'!Q194) -> за м2 а не за штуку | O11: =IF('Все позиции'!R194="","",'Все позиции'!R194)
A12: =IF('Все позиции'!A322="","",'Все позиции'!A322) -> 7. Холодоснабжение 2 этаж | B12: =IF('Все позиции'!B322="","",'Все позиции'!B322) -> 7.2 | C12: =IF('Все позиции'!C322="","",'Все позиции'!C322) -> Подключение фанкойлов в радиусе 2,5 м | D12: =IF('Все позиции'!D322="","",'Все позиции'!D322) -> шт. | E12: =IF('Все позиции'!E322="","",'Все позиции'!E322) -> 31 | F12: =IF('Все позиции'!F322="","",'Все позиции'!F322) -> 5670 | G12: =IF('Все позиции'!H322="","",'Все позиции'!H322) -> 0 | H12: =IF('Все позиции'!L322="","",'Все позиции'!L322) | I12: =IF('Все позиции'!O322="","",'Все позиции'!O322) -> -1 | J12: =IF('Все позиции'!G322="","",'Все позиции'!G322) -> 175770 | K12: =IF('Все позиции'!M322="","",'Все позиции'!M322) -> 0 | L12: =IF('Все позиции'!N322="","",'Все позиции'!N322) -> -175770 | M12: =IF('Все позиции'!P322="","",'Все позиции'!P322) -> Удалено заказчиком без комментария | N12: =IF('Все позиции'!Q322="","",'Все позиции'!Q322) | O12: =IF('Все позиции'!R322="","",'Все позиции'!R322)
A13: =IF('Все позиции'!A329="","",'Все позиции'!A329) -> 7. Холодоснабжение 2 этаж | B13: =IF('Все позиции'!B329="","",'Все позиции'!B329) -> 7.9 | C13: =IF('Все позиции'!C329="","",'Все позиции'!C329) -> демонтаж холодоснабжения | D13: =IF('Все позиции'!D329="","",'Все позиции'!D329) -> к-т | E13: =IF('Все позиции'!E329="","",'Все позиции'!E329) -> 1 | F13: =IF('Все позиции'!F329="","",'Все позиции'!F329) -> 162000 | G13: =IF('Все позиции'!H329="","",'Все позиции'!H329) -> 0 | H13: =IF('Все позиции'!L329="","",'Все позиции'!L329) | I13: =IF('Все позиции'!O329="","",'Все позиции'!O329) -> -1 | J13: =IF('Все позиции'!G329="","",'Все позиции'!G329) -> 162000 | K13: =IF('Все позиции'!M329="","",'Все позиции'!M329) -> 0 | L13: =IF('Все позиции'!N329="","",'Все позиции'!N329) -> -162000 | M13: =IF('Все позиции'!P329="","",'Все позиции'!P329) -> Удалено заказчиком без комментария | N13: =IF('Все позиции'!Q329="","",'Все позиции'!Q329) | O13: =IF('Все позиции'!R329="","",'Все позиции'!R329)
A14: =IF('Все позиции'!A199="","",'Все позиции'!A199) -> 4. Дымоудаление (10 этаж) | B14: =IF('Все позиции'!B199="","",'Все позиции'!B199) -> 4.85 | C14: =IF('Все позиции'!C199="","",'Все позиции'!C199) -> Воздуховод 800*500 | D14: =IF('Все позиции'!D199="","",'Все позиции'!D199) -> м2 | E14: =IF('Все позиции'!E199="","",'Все позиции'!E199) -> 52 | F14: =IF('Все позиции'!F199="","",'Все позиции'!F199) -> 2560 | G14: =IF('Все позиции'!H199="","",'Все позиции'!H199) -> 52 | H14: =IF('Все позиции'!L199="","",'Все позиции'!L199) | I14: =IF('Все позиции'!O199="","",'Все позиции'!O199) -> -1 | J14: =IF('Все позиции'!G199="","",'Все позиции'!G199) -> 133120 | K14: =IF('Все позиции'!M199="","",'Все позиции'!M199) -> 0 | L14: =IF('Все позиции'!N199="","",'Все позиции'!N199) -> -133120 | M14: =IF('Все позиции'!P199="","",'Все позиции'!P199) -> Исключено → отдельный допник | N14: =IF('Все позиции'!Q199="","",'Все позиции'!Q199) -> удалить (если будут данные позиции сделаем отдельный допник) | O14: =IF('Все позиции'!R199="","",'Все позиции'!R199)
A15: =IF('Все позиции'!A48="","",'Все позиции'!A48) -> 2. Кондиционирование | B15: =IF('Все позиции'!B48="","",'Все позиции'!B48) -> 2.9 | C15: =IF('Все позиции'!C48="","",'Все позиции'!C48) -> Трубопровод из полимерных труб РЕХ-а, Дн25х3.5 REHAU Rautitan Flex 11303701006 | D15: =IF('Все позиции'!D48="","",'Все позиции'!D48) -> м.п. | E15: =IF('Все позиции'!E48="","",'Все позиции'!E48) -> 1280 | F15: =IF('Все позиции'!F48="","",'Все позиции'!F48) -> 500 | G15: =IF('Все позиции'!H48="","",'Все позиции'!H48) -> 1280 | H15: =IF('Все позиции'!L48="","",'Все позиции'!L48) -> 400 | I15: =IF('Все позиции'!O48="","",'Все позиции'!O48) -> -0.2 | J15: =IF('Все позиции'!G48="","",'Все позиции'!G48) -> 640000 | K15: =IF('Все позиции'!M48="","",'Все позиции'!M48) -> 512000 | L15: =IF('Все позиции'!N48="","",'Все позиции'!N48) -> -128000 | M15: =IF('Все позиции'!P48="","",'Все позиции'!P48) -> Снижение согласовано, но не внесено в итог | N15: =IF('Все позиции'!Q48="","",'Все позиции'!Q48) -> по договру | O15: =IF('Все позиции'!R48="","",'Все позиции'!R48) -> Цена Согласована Марк
A16: =IF('Все позиции'!A204="","",'Все позиции'!A204) -> 5. Холодоснабжение 10 этаж | B16: =IF('Все позиции'!B204="","",'Все позиции'!B204) -> 5.1 | C16: =IF('Все позиции'!C204="","",'Все позиции'!C204) -> Фанкойл кассетный, 600x600 SK-32 | D16: =IF('Все позиции'!D204="","",'Все позиции'!D204) -> шт. | E16: =IF('Все позиции'!E204="","",'Все позиции'!E204) -> 10 | F16: =IF('Все позиции'!F204="","",'Все позиции'!F204) -> 25920 | G16: =IF('Все позиции'!H204="","",'Все позиции'!H204) -> 10 | H16: =IF('Все позиции'!L204="","",'Все позиции'!L204) -> 14000 | I16: =IF('Все позиции'!O204="","",'Все позиции'!O204) -> -0.45987654 | J16: =IF('Все позиции'!G204="","",'Все позиции'!G204) -> 259200 | K16: =IF('Все позиции'!M204="","",'Все позиции'!M204) -> 140000 | L16: =IF('Все позиции'!N204="","",'Все позиции'!N204) -> -119200 | M16: =IF('Все позиции'!P204="","",'Все позиции'!P204) -> Цена снижена | N16: =IF('Все позиции'!Q204="","",'Все позиции'!Q204) -> в чем разница в 2,5раза от балок? | O16: =IF('Все позиции'!R204="","",'Все позиции'!R204)
A17: =IF('Все позиции'!A238="","",'Все позиции'!A238) -> 5. Холодоснабжение 10 этаж | B17: =IF('Все позиции'!B238="","",'Все позиции'!B238) -> 5.35 | C17: =IF('Все позиции'!C238="","",'Все позиции'!C238) -> Дренаж | D17: =IF('Все позиции'!D238="","",'Все позиции'!D238) -> мп | E17: =IF('Все позиции'!E238="","",'Все позиции'!E238) -> 100 | F17: =IF('Все позиции'!F238="","",'Все позиции'!F238) -> 1092 | G17: =IF('Все позиции'!H238="","",'Все позиции'!H238) -> 0 | H17: =IF('Все позиции'!L238="","",'Все позиции'!L238) | I17: =IF('Все позиции'!O238="","",'Все позиции'!O238) -> -1 | J17: =IF('Все позиции'!G238="","",'Все позиции'!G238) -> 109200 | K17: =IF('Все позиции'!M238="","",'Все позиции'!M238) -> 0 | L17: =IF('Все позиции'!N238="","",'Все позиции'!N238) -> -109200 | M17: =IF('Все позиции'!P238="","",'Все позиции'!P238) -> Удалено заказчиком без комментария | N17: =IF('Все позиции'!Q238="","",'Все позиции'!Q238) | O17: =IF('Все позиции'!R238="","",'Все позиции'!R238)
A18: =IF('Все позиции'!A330="","",'Все позиции'!A330) -> 7. Холодоснабжение 2 этаж | B18: =IF('Все позиции'!B330="","",'Все позиции'!B330) -> 7.10 | C18: =IF('Все позиции'!C330="","",'Все позиции'!C330) -> демонтаж дренажной системы | D18: =IF('Все позиции'!D330="","",'Все позиции'!D330) -> к-т | E18: =IF('Все позиции'!E330="","",'Все позиции'!E330) -> 1 | F18: =IF('Все позиции'!F330="","",'Все позиции'!F330) -> 97200 | G18: =IF('Все позиции'!H330="","",'Все позиции'!H330) -> 0 | H18: =IF('Все позиции'!L330="","",'Все позиции'!L330) | I18: =IF('Все позиции'!O330="","",'Все позиции'!O330) -> -1 | J18: =IF('Все позиции'!G330="","",'Все позиции'!G330) -> 97200 | K18: =IF('Все позиции'!M330="","",'Все позиции'!M330) -> 0 | L18: =IF('Все позиции'!N330="","",'Все позиции'!N330) -> -97200 | M18: =IF('Все позиции'!P330="","",'Все позиции'!P330) -> Удалено заказчиком без комментария | N18: =IF('Все позиции'!Q330="","",'Все позиции'!Q330) | O18: =IF('Все позиции'!R330="","",'Все позиции'!R330)
A19: =IF('Все позиции'!A95="","",'Все позиции'!A95) -> 3. Дополнительные работы 3,7,8,9 этаж | B19: =IF('Все позиции'!B95="","",'Все позиции'!B95) -> 3.13 | C19: =IF('Все позиции'!C95="","",'Все позиции'!C95) -> Перемонтаж щелевых диффузоров | D19: =IF('Все позиции'!D95="","",'Все позиции'!D95) -> к-т | E19: =IF('Все позиции'!E95="","",'Все позиции'!E95) -> 8 | F19: =IF('Все позиции'!F95="","",'Все позиции'!F95) -> 16800 | G19: =IF('Все позиции'!H95="","",'Все позиции'!H95) -> 8 | H19: =IF('Все позиции'!L95="","",'Все позиции'!L95) -> 4800 | I19: =IF('Все позиции'!O95="","",'Все позиции'!O95) -> -0.71428571 | J19: =IF('Все позиции'!G95="","",'Все позиции'!G95) -> 134400 | K19: =IF('Все позиции'!M95="","",'Все позиции'!M95) -> 38400 | L19: =IF('Все позиции'!N95="","",'Все позиции'!N95) -> -96000 | M19: =IF('Все позиции'!P95="","",'Все позиции'!P95) -> Цена снижена | N19: =IF('Все позиции'!Q95="","",'Все позиции'!Q95) -> сильно завышено, что за диффузоры? С КСД? Размер? | O19: =IF('Все позиции'!R95="","",'Все позиции'!R95) -> Демонтаж - монтаж щелевого диффузора. Поставь цену сама
A20: =IF('Все позиции'!A200="","",'Все позиции'!A200) -> 4. Дымоудаление (10 этаж) | B20: =IF('Все позиции'!B200="","",'Все позиции'!B200) -> 4.86 | C20: =IF('Все позиции'!C200="","",'Все позиции'!C200) -> Изоляция М-БОР | D20: =IF('Все позиции'!D200="","",'Все позиции'!D200) -> м2 | E20: =IF('Все позиции'!E200="","",'Все позиции'!E200) -> 66 | F20: =IF('Все позиции'!F200="","",'Все позиции'!F200) -> 1440 | G20: =IF('Все позиции'!H200="","",'Все позиции'!H200) -> 66 | H20: =IF('Все позиции'!L200="","",'Все позиции'!L200) | I20: =IF('Все позиции'!O200="","",'Все позиции'!O200) -> -1 | J20: =IF('Все позиции'!G200="","",'Все позиции'!G200) -> 95040 | K20: =IF('Все позиции'!M200="","",'Все позиции'!M200) -> 0 | L20: =IF('Все позиции'!N200="","",'Все позиции'!N200) -> -95040 | M20: =IF('Все позиции'!P200="","",'Все позиции'!P200) -> Исключено → отдельный допник | N20: =IF('Все позиции'!Q200="","",'Все позиции'!Q200) -> удалить (если будут данные позиции сделаем отдельный допник) | O20: =IF('Все позиции'!R200="","",'Все позиции'!R200)
A21: =IF('Все позиции'!A37="","",'Все позиции'!A37) -> 1. Вентиляция | B21: =IF('Все позиции'!B37="","",'Все позиции'!B37) -> 1.33 | C21: =IF('Все позиции'!C37="","",'Все позиции'!C37) -> Универсальная теплоизоляция в виде рулонов, толщиной 6 мм K- Flex-ST | D21: =IF('Все позиции'!D37="","",'Все позиции'!D37) -> м2 | E21: =IF('Все позиции'!E37="","",'Все позиции'!E37) -> 882 | F21: =IF('Все позиции'!F37="","",'Все позиции'!F37) -> 665.89 | G21: =IF('Все позиции'!H37="","",'Все позиции'!H37) -> 882 | H21: =IF('Все позиции'!L37="","",'Все позиции'!L37) -> 570 | I21: =IF('Все позиции'!O37="","",'Все позиции'!O37) -> -0.14400276 | J21: =IF('Все позиции'!G37="","",'Все позиции'!G37) -> 587314.98 | K21: =IF('Все позиции'!M37="","",'Все позиции'!M37) -> 502740 | L21: =IF('Все позиции'!N37="","",'Все позиции'!N37) -> -84574.98 | M21: =IF('Все позиции'!P37="","",'Все позиции'!P37) -> Снижение согласовано, но не внесено в итог | N21: =IF('Все позиции'!Q37="","",'Все позиции'!Q37) -> р по договору | O21: =IF('Все позиции'!R37="","",'Все позиции'!R37) -> Цена Согласована Марк
A22: =IF('Все позиции'!A49="","",'Все позиции'!A49) -> 2. Кондиционирование | B22: =IF('Все позиции'!B49="","",'Все позиции'!B49) -> 2.10 | C22: =IF('Все позиции'!C49="","",'Все позиции'!C49) -> Трубопровод из полимерных труб РЕХ-а, Дн32х3.5 REHAU Rautitan Flex | D22: =IF('Все позиции'!D49="","",'Все позиции'!D49) -> м.п. | E22: =IF('Все позиции'!E49="","",'Все позиции'!E49) -> 800 | F22: =IF('Все позиции'!F49="","",'Все позиции'!F49) -> 500 | G22: =IF('Все позиции'!H49="","",'Все позиции'!H49) -> 800 | H22: =IF('Все позиции'!L49="","",'Все позиции'!L49) -> 400 | I22: =IF('Все позиции'!O49="","",'Все позиции'!O49) -> -0.2 | J22: =IF('Все позиции'!G49="","",'Все позиции'!G49) -> 400000 | K22: =IF('Все позиции'!M49="","",'Все позиции'!M49) -> 320000 | L22: =IF('Все позиции'!N49="","",'Все позиции'!N49) -> -80000 | M22: =IF('Все позиции'!P49="","",'Все позиции'!P49) -> Снижение согласовано, но не внесено в итог | N22: =IF('Все позиции'!Q49="","",'Все позиции'!Q49) -> по договру | O22: =IF('Все позиции'!R49="","",'Все позиции'!R49) -> Цена Согласована Марк
A23: =IF('Все позиции'!A91="","",'Все позиции'!A91) -> 3. Дополнительные работы 3,7,8,9 этаж | B23: =IF('Все позиции'!B91="","",'Все позиции'!B91) -> 3.9 | C23: =IF('Все позиции'!C91="","",'Все позиции'!C91) -> Монтаж пожарного клапана | D23: =IF('Все позиции'!D91="","",'Все позиции'!D91) -> к-т | E23: =IF('Все позиции'!E91="","",'Все позиции'!E91) -> 4 | F23: =IF('Все позиции'!F91="","",'Все позиции'!F91) -> 21000 | G23: =IF('Все позиции'!H91="","",'Все позиции'!H91) -> 2 | H23: =IF('Все позиции'!L91="","",'Все позиции'!L91) -> 2900 | I23: =IF('Все позиции'!O91="","",'Все позиции'!O91) -> -0.86190476 | J23: =IF('Все позиции'!G91="","",'Все позиции'!G91) -> 84000 | K23: =IF('Все позиции'!M91="","",'Все позиции'!M91) -> 5800 | L23: =IF('Все позиции'!N91="","",'Все позиции'!N91) -> -78200 | M23: =IF('Все позиции'!P91="","",'Все позиции'!P91) -> Снижены цена и количество | N23: =IF('Все позиции'!Q91="","",'Все позиции'!Q91) -> сильно завышена расценка | O23: =IF('Все позиции'!R91="","",'Все позиции'!R91)
A24: =IF('Все позиции'!A197="","",'Все позиции'!A197) -> 4. Вентиляция 10 этаж | B24: =IF('Все позиции'!B197="","",'Все позиции'!B197) -> 4.84 | C24: =IF('Все позиции'!C197="","",'Все позиции'!C197) -> ПНР10этаж | D24: =IF('Все позиции'!D197="","",'Все позиции'!D197) -> к-т | E24: =IF('Все позиции'!E197="","",'Все позиции'!E197) -> 1 | F24: =IF('Все позиции'!F197="","",'Все позиции'!F197) -> 162000 | G24: =IF('Все позиции'!H197="","",'Все позиции'!H197) -> 1 | H24: =IF('Все позиции'!L197="","",'Все позиции'!L197) -> 95000 | I24: =IF('Все позиции'!O197="","",'Все позиции'!O197) -> -0.41358025 | J24: =IF('Все позиции'!G197="","",'Все позиции'!G197) -> 162000 | K24: =IF('Все позиции'!M197="","",'Все позиции'!M197) -> 95000 | L24: =IF('Все позиции'!N197="","",'Все позиции'!N197) -> -67000 | M24: =IF('Все позиции'!P197="","",'Все позиции'!P197) -> Цена снижена | N24: =IF('Все позиции'!Q197="","",'Все позиции'!Q197) -> по тип.эт | O24: =IF('Все позиции'!R197="","",'Все позиции'!R197)
A25: =IF('Все позиции'!A314="","",'Все позиции'!A314) -> 6. Вентиляция 2 этаж | B25: =IF('Все позиции'!B314="","",'Все позиции'!B314) -> 6.74 | C25: =IF('Все позиции'!C314="","",'Все позиции'!C314) -> ПНР 2й этаж | D25: =IF('Все позиции'!D314="","",'Все позиции'!D314) -> к-т | E25: =IF('Все позиции'!E314="","",'Все позиции'!E314) -> 1 | F25: =IF('Все позиции'!F314="","",'Все позиции'!F314) -> 162000 | G25: =IF('Все позиции'!H314="","",'Все позиции'!H314) -> 1 | H25: =IF('Все позиции'!L314="","",'Все позиции'!L314) -> 95000 | I25: =IF('Все позиции'!O314="","",'Все позиции'!O314) -> -0.41358025 | J25: =IF('Все позиции'!G314="","",'Все позиции'!G314) -> 162000 | K25: =IF('Все позиции'!M314="","",'Все позиции'!M314) -> 95000 | L25: =IF('Все позиции'!N314="","",'Все позиции'!N314) -> -67000 | M25: =IF('Все позиции'!P314="","",'Все позиции'!P314) -> Цена снижена | N25: =IF('Все позиции'!Q314="","",'Все позиции'!Q314) -> по тип.эт | O25: =IF('Все позиции'!R314="","",'Все позиции'!R314)
A26: =IF('Все позиции'!A76="","",'Все позиции'!A76) -> 2. Кондиционирование | B26: =IF('Все позиции'!B76="","",'Все позиции'!B76) -> 2.37 | C26: =IF('Все позиции'!C76="","",'Все позиции'!C76) -> Тепловая изоляция из вспененного каучука, толщиной 9 мм Armaflex АСЕ 28*13 | D26: =IF('Все позиции'!D76="","",'Все позиции'!D76) -> м.п. | E26: =IF('Все позиции'!E76="","",'Все позиции'!E76) -> 1280 | F26: =IF('Все позиции'!F76="","",'Все позиции'!F76) -> 200 | G26: =IF('Все позиции'!H76="","",'Все позиции'!H76) -> 1280 | H26: =IF('Все позиции'!L76="","",'Все позиции'!L76) -> 150 | I26: =IF('Все позиции'!O76="","",'Все позиции'!O76) -> -0.25 | J26: =IF('Все позиции'!G76="","",'Все позиции'!G76) -> 256000 | K26: =IF('Все позиции'!M76="","",'Все позиции'!M76) -> 192000 | L26: =IF('Все позиции'!N76="","",'Все позиции'!N76) -> -64000 | M26: =IF('Все позиции'!P76="","",'Все позиции'!P76) -> Снижение согласовано, но не внесено в итог | N26: =IF('Все позиции'!Q76="","",'Все позиции'!Q76) -> по договору | O26: =IF('Все позиции'!R76="","",'Все позиции'!R76) -> Цена Согласована Марк
A27: =IF('Все позиции'!A236="","",'Все позиции'!A236) -> 5. Холодоснабжение 10 этаж | B27: =IF('Все позиции'!B236="","",'Все позиции'!B236) -> 5.33 | C27: =IF('Все позиции'!C236="","",'Все позиции'!C236) -> Трубки теплоизоляционные для трубы Ø32х5,4 толщиной 6мм | D27: =IF('Все позиции'!D236="","",'Все позиции'!D236) -> шт. | E27: =IF('Все позиции'!E236="","",'Все позиции'!E236) -> 75 | F27: =IF('Все позиции'!F236="","",'Все позиции'!F236) -> 1020 | G27: =IF('Все позиции'!H236="","",'Все позиции'!H236) -> 75 | H27: =IF('Все позиции'!L236="","",'Все позиции'!L236) -> 200 | I27: =IF('Все позиции'!O236="","",'Все позиции'!O236) -> -0.80392157 | J27: =IF('Все позиции'!G236="","",'Все позиции'!G236) -> 76500 | K27: =IF('Все позиции'!M236="","",'Все позиции'!M236) -> 15000 | L27: =IF('Все позиции'!N236="","",'Все позиции'!N236) -> -61500 | M27: =IF('Все позиции'!P236="","",'Все позиции'!P236) -> Цена снижена | N27: =IF('Все позиции'!Q236="","",'Все позиции'!Q236) -> по договору | O27: =IF('Все позиции'!R236="","",'Все позиции'!R236) -> Цена Согласована Марк
A28: =IF('Все позиции'!A195="","",'Все позиции'!A195) -> 4. Вентиляция 10 этаж | B28: =IF('Все позиции'!B195="","",'Все позиции'!B195) -> 4.82 | C28: =IF('Все позиции'!C195="","",'Все позиции'!C195) -> Изоляция прямоугольных воздуховодов | D28: =IF('Все позиции'!D195="","",'Все позиции'!D195) -> м2 | E28: =IF('Все позиции'!E195="","",'Все позиции'!E195) -> 120 | F28: =IF('Все позиции'!F195="","",'Все позиции'!F195) -> 1092 | G28: =IF('Все позиции'!H195="","",'Все позиции'!H195) -> 120 | H28: =IF('Все позиции'!L195="","",'Все позиции'!L195) -> 665 | I28: =IF('Все позиции'!O195="","",'Все позиции'!O195) -> -0.39102564 | J28: =IF('Все позиции'!G195="","",'Все позиции'!G195) -> 131040 | K28: =IF('Все позиции'!M195="","",'Все позиции'!M195) -> 79800 | L28: =IF('Все позиции'!N195="","",'Все позиции'!N195) -> -51240 | M28: =IF('Все позиции'!P195="","",'Все позиции'!P195) -> Цена снижена | N28: =IF('Все позиции'!Q195="","",'Все позиции'!Q195) | O28: =IF('Все позиции'!R195="","",'Все позиции'!R195)
A29: =IF('Все позиции'!A319="","",'Все позиции'!A319) -> 6. Дымоудаление (2 этаж) | B29: =IF('Все позиции'!B319="","",'Все позиции'!B319) -> 6.78 | C29: =IF('Все позиции'!C319="","",'Все позиции'!C319) -> Отвод 45гр 800*500 | D29: =IF('Все позиции'!D319="","",'Все позиции'!D319) -> шт. | E29: =IF('Все позиции'!E319="","",'Все позиции'!E319) -> 6 | F29: =IF('Все позиции'!F319="","",'Все позиции'!F319) -> 8000 | G29: =IF('Все позиции'!H319="","",'Все позиции'!H319) -> 6 | H29: =IF('Все позиции'!L319="","",'Все позиции'!L319) | I29: =IF('Все позиции'!O319="","",'Все позиции'!O319) -> -1 | J29: =IF('Все позиции'!G319="","",'Все позиции'!G319) -> 48000 | K29: =IF('Все позиции'!M319="","",'Все позиции'!M319) -> 0 | L29: =IF('Все позиции'!N319="","",'Все позиции'!N319) -> -48000 | M29: =IF('Все позиции'!P319="","",'Все позиции'!P319) -> Исключено → отдельный допник | N29: =IF('Все позиции'!Q319="","",'Все позиции'!Q319) -> удалить (если будут данные позиции сделаем отдельный допник) | O29: =IF('Все позиции'!R319="","",'Все позиции'!R319)
A30: =IF('Все позиции'!A243="","",'Все позиции'!A243) -> 6. Вентиляция 2 этаж | B30: =IF('Все позиции'!B243="","",'Все позиции'!B243) -> 6.3 | C30: =IF('Все позиции'!C243="","",'Все позиции'!C243) -> Решетка защитная круглая, Ø200 БСК 200 | D30: =IF('Все позиции'!D243="","",'Все позиции'!D243) -> шт. | E30: =IF('Все позиции'!E243="","",'Все позиции'!E243) -> 44 | F30: =IF('Все позиции'!F243="","",'Все позиции'!F243) -> 1296 | G30: =IF('Все позиции'!H243="","",'Все позиции'!H243) -> 44 | H30: =IF('Все позиции'!L243="","",'Все позиции'!L243) -> 298.89 | I30: =IF('Все позиции'!O243="","",'Все позиции'!O243) -> -0.769375 | J30: =IF('Все позиции'!G243="","",'Все позиции'!G243) -> 57024 | K30: =IF('Все позиции'!M243="","",'Все позиции'!M243) -> 13151.16 | L30: =IF('Все позиции'!N243="","",'Все позиции'!N243) -> -43872.84 | M30: =IF('Все позиции'!P243="","",'Все позиции'!P243) -> Снижение предложено, но не внесено в итог | N30: =IF('Все позиции'!Q243="","",'Все позиции'!Q243) -> по договору | O30: =IF('Все позиции'!R243="","",'Все позиции'!R243)
A31: =IF('Все позиции'!A312="","",'Все позиции'!A312) -> 6. Вентиляция 2 этаж | B31: =IF('Все позиции'!B312="","",'Все позиции'!B312) -> 6.72 | C31: =IF('Все позиции'!C312="","",'Все позиции'!C312) -> Изоляция прямоугольных воздуховодов | D31: =IF('Все позиции'!D312="","",'Все позиции'!D312) -> м2 | E31: =IF('Все позиции'!E312="","",'Все позиции'!E312) -> 150 | F31: =IF('Все позиции'!F312="","",'Все позиции'!F312) -> 1092 | G31: =IF('Все позиции'!H312="","",'Все позиции'!H312) -> 150 | H31: =IF('Все позиции'!L312="","",'Все позиции'!L312) -> 800 | I31: =IF('Все позиции'!O312="","",'Все позиции'!O312) -> -0.26739927 | J31: =IF('Все позиции'!G312="","",'Все позиции'!G312) -> 163800 | K31: =IF('Все позиции'!M312="","",'Все позиции'!M312) -> 120000 | L31: =IF('Все позиции'!N312="","",'Все позиции'!N312) -> -43800 | M31: =IF('Все позиции'!P312="","",'Все позиции'!P312) -> Цена снижена | N31: =IF('Все позиции'!Q312="","",'Все позиции'!Q312) | O31: =IF('Все позиции'!R312="","",'Все позиции'!R312)
A32: =IF('Все позиции'!A239="","",'Все позиции'!A239) -> 5. Холодоснабжение 10 этаж | B32: =IF('Все позиции'!B239="","",'Все позиции'!B239) -> 5.36 | C32: =IF('Все позиции'!C239="","",'Все позиции'!C239) -> ПНР 10й этаж | D32: =IF('Все позиции'!D239="","",'Все позиции'!D239) -> к-т | E32: =IF('Все позиции'!E239="","",'Все позиции'!E239) -> 1 | F32: =IF('Все позиции'!F239="","",'Все позиции'!F239) -> 162000 | G32: =IF('Все позиции'!H239="","",'Все позиции'!H239) -> 1 | H32: =IF('Все позиции'!L239="","",'Все позиции'!L239) -> 120000 | I32: =IF('Все позиции'!O239="","",'Все позиции'!O239) -> -0.25925926 | J32: =IF('Все позиции'!G239="","",'Все позиции'!G239) -> 162000 | K32: =IF('Все позиции'!M239="","",'Все позиции'!M239) -> 120000 | L32: =IF('Все позиции'!N239="","",'Все позиции'!N239) -> -42000 | M32: =IF('Все позиции'!P239="","",'Все позиции'!P239) -> Цена снижена | N32: =IF('Все позиции'!Q239="","",'Все позиции'!Q239) -> по тип.эт | O32: =IF('Все позиции'!R239="","",'Все позиции'!R239)
A33: =IF('Все позиции'!A331="","",'Все позиции'!A331) -> 7. Холодоснабжение 2 этаж | B33: =IF('Все позиции'!B331="","",'Все позиции'!B331) -> 7.11 | C33: =IF('Все позиции'!C331="","",'Все позиции'!C331) -> ПНР 2й этаж | D33: =IF('Все позиции'!D331="","",'Все позиции'!D331) -> к-т | E33: =IF('Все позиции'!E331="","",'Все позиции'!E331) -> 1 | F33: =IF('Все позиции'!F331="","",'Все позиции'!F331) -> 162000 | G33: =IF('Все позиции'!H331="","",'Все позиции'!H331) -> 1 | H33: =IF('Все позиции'!L331="","",'Все позиции'!L331) -> 120000 | I33: =IF('Все позиции'!O331="","",'Все позиции'!O331) -> -0.25925926 | J33: =IF('Все позиции'!G331="","",'Все позиции'!G331) -> 162000 | K33: =IF('Все позиции'!M331="","",'Все позиции'!M331) -> 120000 | L33: =IF('Все позиции'!N331="","",'Все позиции'!N331) -> -42000 | M33: =IF('Все позиции'!P331="","",'Все позиции'!P331) -> Цена снижена | N33: =IF('Все позиции'!Q331="","",'Все позиции'!Q331) -> по тип.эт | O33: =IF('Все позиции'!R331="","",'Все позиции'!R331)
A34: =IF('Все позиции'!A120="","",'Все позиции'!A120) -> 4. Вентиляция 10 этаж | B34: =IF('Все позиции'!B120="","",'Все позиции'!B120) -> 4.7 | C34: =IF('Все позиции'!C120="","",'Все позиции'!C120) -> Адаптер для щелевой решетки с регулятором расхода и увеличенным патрубком, 1000мм Адаптер для ЛРЩ 22-1-1000 y=67мм + заслонка | D34: =IF('Все позиции'!D120="","",'Все позиции'!D120) -> шт. | E34: =IF('Все позиции'!E120="","",'Все позиции'!E120) -> 12 | F34: =IF('Все позиции'!F120="","",'Все позиции'!F120) -> 4860 | G34: =IF('Все позиции'!H120="","",'Все позиции'!H120) -> 12 | H34: =IF('Все позиции'!L120="","",'Все позиции'!L120) -> 1500 | I34: =IF('Все позиции'!O120="","",'Все позиции'!O120) -> -0.69135802 | J34: =IF('Все позиции'!G120="","",'Все позиции'!G120) -> 58320 | K34: =IF('Все позиции'!M120="","",'Все позиции'!M120) -> 18000 | L34: =IF('Все позиции'!N120="","",'Все позиции'!N120) -> -40320 | M34: =IF('Все позиции'!P120="","",'Все позиции'!P120) -> Цена снижена | N34: =IF('Все позиции'!Q120="","",'Все позиции'!Q120) -> расценка сильно завышена | O34: =IF('Все позиции'!R120="","",'Все позиции'!R120)
A35: =IF('Все позиции'!A77="","",'Все позиции'!A77) -> 2. Кондиционирование | B35: =IF('Все позиции'!B77="","",'Все позиции'!B77) -> 2.38 | C35: =IF('Все позиции'!C77="","",'Все позиции'!C77) -> Тепловая изоляция из вспененного каучука, толщиной 9 мм Armaflex АСЕ 35*13 | D35: =IF('Все позиции'!D77="","",'Все позиции'!D77) -> м.п. | E35: =IF('Все позиции'!E77="","",'Все позиции'!E77) -> 800 | F35: =IF('Все позиции'!F77="","",'Все позиции'!F77) -> 200 | G35: =IF('Все позиции'!H77="","",'Все позиции'!H77) -> 800 | H35: =IF('Все позиции'!L77="","",'Все позиции'!L77) -> 150 | I35: =IF('Все позиции'!O77="","",'Все позиции'!O77) -> -0.25 | J35: =IF('Все позиции'!G77="","",'Все позиции'!G77) -> 160000 | K35: =IF('Все позиции'!M77="","",'Все позиции'!M77) -> 120000 | L35: =IF('Все позиции'!N77="","",'Все позиции'!N77) -> -40000 | M35: =IF('Все позиции'!P77="","",'Все позиции'!P77) -> Снижение согласовано, но не внесено в итог | N35: =IF('Все позиции'!Q77="","",'Все позиции'!Q77) -> по договору | O35: =IF('Все позиции'!R77="","",'Все позиции'!R77) -> Цена Согласована Марк
A36: =IF('Все позиции'!A211="","",'Все позиции'!A211) -> 5. Холодоснабжение 10 этаж | B36: =IF('Все позиции'!B211="","",'Все позиции'!B211) -> 5.8 | C36: =IF('Все позиции'!C211="","",'Все позиции'!C211) -> Ниппель 3/4" | D36: =IF('Все позиции'!D211="","",'Все позиции'!D211) -> шт. | E36: =IF('Все позиции'!E211="","",'Все позиции'!E211) -> 62 | F36: =IF('Все позиции'!F211="","",'Все позиции'!F211) -> 1296 | G36: =IF('Все позиции'!H211="","",'Все позиции'!H211) -> 62 | H36: =IF('Все позиции'!L211="","",'Все позиции'!L211) -> 700 | I36: =IF('Все позиции'!O211="","",'Все позиции'!O211) -> -0.45987654 | J36: =IF('Все позиции'!G211="","",'Все позиции'!G211) -> 80352 | K36: =IF('Все позиции'!M211="","",'Все позиции'!M211) -> 43400 | L36: =IF('Все позиции'!N211="","",'Все позиции'!N211) -> -36952 | M36: =IF('Все позиции'!P211="","",'Все позиции'!P211) -> Цена снижена | N36: =IF('Все позиции'!Q211="","",'Все позиции'!Q211) | O36: =IF('Все позиции'!R211="","",'Все позиции'!R211) -> Цена Согласована Марк
A37: =IF('Все позиции'!A212="","",'Все позиции'!A212) -> 5. Холодоснабжение 10 этаж | B37: =IF('Все позиции'!B212="","",'Все позиции'!B212) -> 5.9 | C37: =IF('Все позиции'!C212="","",'Все позиции'!C212) -> Муфта переходная 3/4"x 1/2" | D37: =IF('Все позиции'!D212="","",'Все позиции'!D212) -> шт. | E37: =IF('Все позиции'!E212="","",'Все позиции'!E212) -> 62 | F37: =IF('Все позиции'!F212="","",'Все позиции'!F212) -> 1296 | G37: =IF('Все позиции'!H212="","",'Все позиции'!H212) -> 62 | H37: =IF('Все позиции'!L212="","",'Все позиции'!L212) -> 700 | I37: =IF('Все позиции'!O212="","",'Все позиции'!O212) -> -0.45987654 | J37: =IF('Все позиции'!G212="","",'Все позиции'!G212) -> 80352 | K37: =IF('Все позиции'!M212="","",'Все позиции'!M212) -> 43400 | L37: =IF('Все позиции'!N212="","",'Все позиции'!N212) -> -36952 | M37: =IF('Все позиции'!P212="","",'Все позиции'!P212) -> Цена снижена | N37: =IF('Все позиции'!Q212="","",'Все позиции'!Q212) | O37: =IF('Все позиции'!R212="","",'Все позиции'!R212) -> Цена Согласована Марк
A38: =IF('Все позиции'!A213="","",'Все позиции'!A213) -> 5. Холодоснабжение 10 этаж | B38: =IF('Все позиции'!B213="","",'Все позиции'!B213) -> 5.10 | C38: =IF('Все позиции'!C213="","",'Все позиции'!C213) -> Гибкая подводка 3/4" гайка/штуцер, длиной 500мм | D38: =IF('Все позиции'!D213="","",'Все позиции'!D213) -> шт. | E38: =IF('Все позиции'!E213="","",'Все позиции'!E213) -> 62 | F38: =IF('Все позиции'!F213="","",'Все позиции'!F213) -> 1296 | G38: =IF('Все позиции'!H213="","",'Все позиции'!H213) -> 62 | H38: =IF('Все позиции'!L213="","",'Все позиции'!L213) -> 700 | I38: =IF('Все позиции'!O213="","",'Все позиции'!O213) -> -0.45987654 | J38: =IF('Все позиции'!G213="","",'Все позиции'!G213) -> 80352 | K38: =IF('Все позиции'!M213="","",'Все позиции'!M213) -> 43400 | L38: =IF('Все позиции'!N213="","",'Все позиции'!N213) -> -36952 | M38: =IF('Все позиции'!P213="","",'Все позиции'!P213) -> Цена снижена | N38: =IF('Все позиции'!Q213="","",'Все позиции'!Q213) | O38: =IF('Все позиции'!R213="","",'Все позиции'!R213) -> Цена Согласована Марк
A39: =IF('Все позиции'!A214="","",'Все позиции'!A214) -> 5. Холодоснабжение 10 этаж | B39: =IF('Все позиции'!B214="","",'Все позиции'!B214) -> 5.11 | C39: =IF('Все позиции'!C214="","",'Все позиции'!C214) -> Ниппель переходной 3/4" | D39: =IF('Все позиции'!D214="","",'Все позиции'!D214) -> шт. | E39: =IF('Все позиции'!E214="","",'Все позиции'!E214) -> 62 | F39: =IF('Все позиции'!F214="","",'Все позиции'!F214) -> 1296 | G39: =IF('Все позиции'!H214="","",'Все позиции'!H214) -> 62 | H39: =IF('Все позиции'!L214="","",'Все позиции'!L214) -> 700 | I39: =IF('Все позиции'!O214="","",'Все позиции'!O214) -> -0.45987654 | J39: =IF('Все позиции'!G214="","",'Все позиции'!G214) -> 80352 | K39: =IF('Все позиции'!M214="","",'Все позиции'!M214) -> 43400 | L39: =IF('Все позиции'!N214="","",'Все позиции'!N214) -> -36952 | M39: =IF('Все позиции'!P214="","",'Все позиции'!P214) -> Цена снижена | N39: =IF('Все позиции'!Q214="","",'Все позиции'!Q214) | O39: =IF('Все позиции'!R214="","",'Все позиции'!R214) -> Цена Согласована Марк
A40: =IF('Все позиции'!A215="","",'Все позиции'!A215) -> 5. Холодоснабжение 10 этаж | B40: =IF('Все позиции'!B215="","",'Все позиции'!B215) -> 5.12 | C40: =IF('Все позиции'!C215="","",'Все позиции'!C215) -> Переходник 32-R 3/4 | D40: =IF('Все позиции'!D215="","",'Все позиции'!D215) -> шт. | E40: =IF('Все позиции'!E215="","",'Все позиции'!E215) -> 62 | F40: =IF('Все позиции'!F215="","",'Все позиции'!F215) -> 1296 | G40: =IF('Все позиции'!H215="","",'Все позиции'!H215) -> 62 | H40: =IF('Все позиции'!L215="","",'Все позиции'!L215) -> 700 | I40: =IF('Все позиции'!O215="","",'Все позиции'!O215) -> -0.45987654 | J40: =IF('Все позиции'!G215="","",'Все позиции'!G215) -> 80352 | K40: =IF('Все позиции'!M215="","",'Все позиции'!M215) -> 43400 | L40: =IF('Все позиции'!N215="","",'Все позиции'!N215) -> -36952 | M40: =IF('Все позиции'!P215="","",'Все позиции'!P215) -> Цена снижена | N40: =IF('Все позиции'!Q215="","",'Все позиции'!Q215) | O40: =IF('Все позиции'!R215="","",'Все позиции'!R215) -> Цена Согласована Марк
...

Sheet Что оспорить
A1: Что можно оспорить и где есть риски
A2: «Потенциал» — сколько можно вернуть, если отстоять нашу позицию. «Риск» — где заказчик ошибся в нашу пользу и может поправить позже (сумма с минусом).
A3: Тип | B3: Позиции | C3: Что сделал заказчик | D3: Наш аргумент | E3: Сумма, ₽
A4: Потенциал | B4: 5.35, 6.71, 7.2, 7.8, 7.9, 7.10 (дренаж, демонтаж воздуховодов, подключение фанкойлов, демонтаж холодоснабжения и дренажа) | C4: Строки просто удалены из КП, без единого комментария. | D4: Работы выполняются/нужны. Требовать вернуть позиции или письменно обосновать исключение. | E4: ='Все позиции'!G238+'Все позиции'!G311+'Все позиции'!G322+'Все позиции'!G328+'Все позиции'!G329+'Все позиции'!G330 -> 1151370
A5: Потенциал | B5: 6.1–6.3 Решётка защитная круглая Ø100/Ø160/Ø200 (2 этаж) | C5: Предлагают 185 / 205,66 / 298,89 ₽ вместо 1 296 ₽ «по договору». | D5: В этом же КП п. 2.2–2.3 такие же решётки Ø160/Ø200 стоят 1 425 ₽ и приняты без вопросов, а на 10 этаже (п. 4.1) та же решётка Ø100 оставлена по 1 296 ₽. | E5: =-('Все позиции'!N241+'Все позиции'!N242+'Все позиции'!N243) -> 48296.18
A6: Потенциал | B6: 4.76–4.79, 6.65–6.68 Ниппели оцинкованные (10 и 2 этаж) | C6: Поставили 370 ₽/шт. | D6: В п. 3.8 «Ниппель ф160» стоит 630 ₽ и принят заказчиком без правок. Просить минимум 630 ₽. | E6: ='Все позиции'!H189*(630-'Все позиции'!L189)+'Все позиции'!H190*(630-'Все позиции'!L190)+'Все позиции'!H191*(630-'Все позиции'!L191)+'Все позиции'!H192*(630-'Все позиции'!L192)+'Все позиции'!H305*(630-'Все позиции'!L305)+'Все позиции'!H306*(630-'Все позиции'!L306)+'Все позиции'!H307*(630-'Все позиции'!L307)+'Все позиции'!H308*(630-'Все позиции'!L308) -> 24960
A7: Потенциал | B7: 4.56–4.66 Врезки, седла, тройник, переходы круглые (10 этаж) | C7: Поставили 370–440 ₽/шт. | D7: Ровно такие же изделия на 2 этаже (п. 6.48–6.56) заказчик сам оценил в 855 ₽; тройники и переходы по договору (п. 1.17–1.19) — 855 ₽. | E7: ='Все позиции'!H169*(855-'Все позиции'!L169)+'Все позиции'!H170*(855-'Все позиции'!L170)+'Все позиции'!H171*(855-'Все позиции'!L171)+'Все позиции'!H172*(855-'Все позиции'!L172)+'Все позиции'!H173*(855-'Все позиции'!L173)+'Все позиции'!H174*(855-'Все позиции'!L174)+'Все позиции'!H175*(855-'Все позиции'!L175)+'Все позиции'!H176*(855-'Все позиции'!L176)+'Все позиции'!H177*(855-'Все позиции'!L177)+'Все позиции'!H178*(855-'Все позиции'!L178)+'Все позиции'!H179*(855-'Все позиции'!L179) -> 18775
A8: Потенциал | B8: 4.82–4.83 Изоляция воздуховодов (10 этаж) | C8: Поставили 665 ₽. | D8: На 2 этаже (п. 6.72–6.73) та же работа — 800 ₽. | E8: ='Все позиции'!H195*(800-'Все позиции'!L195)+'Все позиции'!H196*(800-'Все позиции'!L196) -> 27135
A9: Потенциал | B9: 6.25 Отвод 15° Ø200 (2 этаж) | C9: Поставили 340 ₽. | D9: Все остальные круглые отводы — 855 ₽ «по договору». | E9: ='Все позиции'!H265*(855-'Все позиции'!L265) -> 1030
A10: Потенциал | B10: 6.64 Заглушка 400×200 (2 этаж) | C10: Поставили 370 ₽. | D10: Круглая заглушка Ø200 (п. 6.63) — 855 ₽; прямоугольная сложнее круглой. | E10: ='Все позиции'!H304*(855-'Все позиции'!L304) -> 970
A11: Отложено | B11: Дымоудаление: 4.85–4.88 и 6.75–6.78 | C11: Исключено, обещают «отдельный допник». | D11: Зафиксировать письменно сроки и цены допсоглашения, иначе это прямые потери. | E11: ='Все позиции'!G199+'Все позиции'!G200+'Все позиции'!G201+'Все позиции'!G202+'Все позиции'!G316+'Все позиции'!G317+'Все позиции'!G318+'Все позиции'!G319 -> 1028480
A12: Информация | B12: 9 позиций с пометкой «Цена согласована Марк» / «по договору» (1.33, 2.9, 2.10, 2.37, 2.38, 6.1–6.3, 7.7) | C12: Снижение написано в комментарии, но в итог их файла (16,53 млн) ещё не внесено. | D12: Итоговая сумма заказчика после внесения этих правок станет ниже. Уже учтено в листах «Сводка» и «Где занизили». | E12: =('Все позиции'!N37+'Все позиции'!N48+'Все позиции'!N49+'Все позиции'!N76+'Все позиции'!N77+'Все позиции'!N241+'Все позиции'!N242+'Все позиции'!N243+'Все позиции'!N327) -> -452611.16
A13: Риск | B13: 7.5–7.6 Клапан балансировочный / комплект трёхходового клапана (2 этаж) | C13: Поставили 1 994 ₽, а в комментарии пишут «в п. 5.5 стоит 1944». | D13: Опечатка в нашу пользу: если исправят на 1 944, потеряем ещё. | E13: =-('Все позиции'!H325+'Все позиции'!H326)*50 -> -3100
A14: Риск | B14: 4.24–4.26, 6.16–6.18 Воздуховоды оцинк. Ø125/Ø160/Ø200 | C14: Цены по договору «съехали» на строку: Ø160 — 862,23 (по договору п. 1.14 — 689,79), Ø200 на 10 эт. — 1 077,79 (по договору п. 1.15 — 862,23). | D14: Ошибка в нашу пользу; при перепроверке могут снизить. | E14: =-(('Все позиции'!H138+'Все позиции'!H257)*(862.23-689.79)+'Все позиции'!H139*(1077.79-862.23)) -> -10648.32
A15: Риск | B15: 6.69–6.70 Изоляция изделий (2 этаж) | C15: Оставили 1 296 и 3 240 ₽, хотя на 10 этаже те же позиции снизили до 450 и 665 ₽. | D15: Скорее всего пропустили; могут снизить следом. | E15: =-('Все позиции'!H309*('Все позиции'!L309-450)+'Все позиции'!H310*('Все позиции'!L310-665)) -> -3421
D16: Итого потенциал к возврату (без допника по дымоудалению) | E16: =SUMIFS(E4:E15,A4:A15,"Потенциал") -> 1272536.2
D17: Итого риски (могут снизить дополнительно) | E17: =SUMIFS(E4:E15,A4:A15,"Риск") -> -17169.32

Sheet Все позиции
A1: Сравнение КП: наше исходное vs исправленное заказчиком (Договор № СПБ-ГАЗЭ/ОВ/7-9, ул. Стартовая, д. 6, к. 2)
A2: Минус в столбце «Разница» — на сколько нам занизили. Жёлтые строки — снижение заказчик написал в комментарии, но в итог своего файла ещё не внёс. Все суммы без НДС.
A3: Раздел | B3: № | C3: Наименование | D3: Ед. | E3: Кол-во (наше КП) | F3: Цена за ед. (наше КП), ₽ | G3: Сумма (наше КП), ₽ | H3: Кол-во (заказчик) | I3: Цена в файле заказчика, ₽ | J3: Сумма в файле заказчика, ₽ | K3: Цена из комментария заказчика (не внесена в итог файла), ₽ | L3: Итоговая цена с учётом всех правок, ₽ | M3: Итоговая сумма с учётом всех правок, ₽ | N3: Разница, ₽ (итог − наше КП) | O3: Изменение цены, % | P3: Что произошло | Q3: Комментарий заказчика | R3: Ответ / согласование (из файла заказчика)
B4: 1. Вентиляция
A5: 1. Вентиляция | B5: 1.1 | C5: Диффузор 160 мм | D5: шт | E5: 72 | F5: 600 | G5: =E5*F5 -> 43200 | H5: 72 | I5: 600 | J5: =H5*I5 -> 43200 | L5: =IF(K5<>"",K5,I5) -> 600 | M5: =H5*L5 -> 43200 | N5: =M5-G5 -> 0 | O5: =IF(F5>0,L5/F5-1,"") -> 0 | P5: Без изменений
A6: 1. Вентиляция | B6: 1.2 | C6: Диффузор 160 мм (сущ) исключено | D6: шт | E6: 0 | F6: 0 | G6: =E6*F6 -> 0 | H6: 0 | J6: =H6*I6 -> 0 | L6: =IF(K6<>"",K6,I6) -> 0 | M6: =H6*L6 -> 0 | N6: =M6-G6 -> 0 | O6: =IF(F6>0,L6/F6-1,"") | P6: Без изменений
A7: 1. Вентиляция | B7: 1.3 | C7: Диффузор 100 мм | D7: шт | E7: 8 | F7: 600 | G7: =E7*F7 -> 4800 | H7: 8 | I7: 600 | J7: =H7*I7 -> 4800 | L7: =IF(K7<>"",K7,I7) -> 600 | M7: =H7*L7 -> 4800 | N7: =M7-G7 -> 0 | O7: =IF(F7>0,L7/F7-1,"") -> 0 | P7: Без изменений
A8: 1. Вентиляция | B8: 1.4 | C8: Решетка щелевая SWANa 2-1200 (сущ) исключено | D8: шт | E8: 0 | F8: 0 | G8: =E8*F8 -> 0 | H8: 0 | J8: =H8*I8 -> 0 | L8: =IF(K8<>"",K8,I8) -> 0 | M8: =H8*L8 -> 0 | N8: =M8-G8 -> 0 | O8: =IF(F8>0,L8/F8-1,"") | P8: Без изменений
A9: 1. Вентиляция | B9: 1.5 | C9: Регулятор расхода воздуха, Ø100 | D9: шт | E9: 12 | F9: 950 | G9: =E9*F9 -> 11400 | H9: 12 | I9: 950 | J9: =H9*I9 -> 11400 | L9: =IF(K9<>"",K9,I9) -> 950 | M9: =H9*L9 -> 11400 | N9: =M9-G9 -> 0 | O9: =IF(F9>0,L9/F9-1,"") -> 0 | P9: Без изменений
A10: 1. Вентиляция | B10: 1.6 | C10: Регулятор расхода воздуха, Ø160 | D10: шт | E10: 60 | F10: 950 | G10: =E10*F10 -> 57000 | H10: 60 | I10: 950 | J10: =H10*I10 -> 57000 | L10: =IF(K10<>"",K10,I10) -> 950 | M10: =H10*L10 -> 57000 | N10: =M10-G10 -> 0 | O10: =IF(F10>0,L10/F10-1,"") -> 0 | P10: Без изменений
A11: 1. Вентиляция | B11: 1.7 | C11: Регулятор расхода воздуха, Ø200 | D11: шт | E11: 64 | F11: 950 | G11: =E11*F11 -> 60800 | H11: 64 | I11: 950 | J11: =H11*I11 -> 60800 | L11: =IF(K11<>"",K11,I11) -> 950 | M11: =H11*L11 -> 60800 | N11: =M11-G11 -> 0 | O11: =IF(F11>0,L11/F11-1,"") -> 0 | P11: Без изменений
A12: 1. Вентиляция | B12: 1.8 | C12: Регулятор расхода воздуха, Ø250 | D12: шт | E12: 8 | F12: 950 | G12: =E12*F12 -> 7600 | H12: 8 | I12: 950 | J12: =H12*I12 -> 7600 | L12: =IF(K12<>"",K12,I12) -> 950 | M12: =H12*L12 -> 7600 | N12: =M12-G12 -> 0 | O12: =IF(F12>0,L12/F12-1,"") -> 0 | P12: Без изменений
A13: 1. Вентиляция | B13: 1.9 | C13: Воздуховод гофрированный 160 исключено | D13: м | E13: 0 | F13: 0 | G13: =E13*F13 -> 0 | H13: 0 | J13: =H13*I13 -> 0 | L13: =IF(K13<>"",K13,I13) -> 0 | M13: =H13*L13 -> 0 | N13: =M13-G13 -> 0 | O13: =IF(F13>0,L13/F13-1,"") | P13: Без изменений
A14: 1. Вентиляция | B14: 1.10 | C14: Воздуховод гофрированный 100 | D14: м | E14: 13.5 | F14: 760 | G14: =E14*F14 -> 10260 | H14: 13.5 | I14: 760 | J14: =H14*I14 -> 10260 | L14: =IF(K14<>"",K14,I14) -> 760 | M14: =H14*L14 -> 10260 | N14: =M14-G14 -> 0 | O14: =IF(F14>0,L14/F14-1,"") -> 0 | P14: Без изменений
A15: 1. Вентиляция | B15: 1.11 | C15: Воздуховод гофрированный Ø160 алюдек | D15: м | E15: 26.5 | F15: 760 | G15: =E15*F15 -> 20140 | H15: 26.5 | I15: 760 | J15: =H15*I15 -> 20140 | L15: =IF(K15<>"",K15,I15) -> 760 | M15: =H15*L15 -> 20140 | N15: =M15-G15 -> 0 | O15: =IF(F15>0,L15/F15-1,"") -> 0 | P15: Без изменений
A16: 1. Вентиляция | B16: 1.12 | C16: Воздуховод гофрированный изолированный, Ø160 санодек | D16: м | E16: 50 | F16: 760 | G16: =E16*F16 -> 38000 | H16: 50 | I16: 760 | J16: =H16*I16 -> 38000 | L16: =IF(K16<>"",K16,I16) -> 760 | M16: =H16*L16 -> 38000 | N16: =M16-G16 -> 0 | O16: =IF(F16>0,L16/F16-1,"") -> 0 | P16: Без изменений
A17: 1. Вентиляция | B17: 1.13 | C17: Воздуховод(класс герм. "В") толщина лист. стали b-0,5мм 100 - | D17: м | E17: 5.2 | F17: 950 | G17: =E17*F17 -> 4940 | H17: 5.2 | I17: 950 | J17: =H17*I17 -> 4940 | L17: =IF(K17<>"",K17,I17) -> 950 | M17: =H17*L17 -> 4940 | N17: =M17-G17 -> 0 | O17: =IF(F17>0,L17/F17-1,"") -> 0 | P17: Без изменений
A18: 1. Вентиляция | B18: 1.14 | C18: Воздуховод(класс герм. "В") толщина лист. стали b-0,5мм 160 | D18: м | E18: 771.3 | F18: 689.79 | G18: =E18*F18 -> 532035.03 | H18: 771.3 | I18: 689.79 | J18: =H18*I18 -> 532035.03 | L18: =IF(K18<>"",K18,I18) -> 689.79 | M18: =H18*L18 -> 532035.03 | N18: =M18-G18 -> 0 | O18: =IF(F18>0,L18/F18-1,"") -> 0 | P18: Без изменений
A19: 1. Вентиляция | B19: 1.15 | C19: Воздуховод(класс герм. "В") толщина лист. стали b-0,5мм 200 | D19: м | E19: 204.6 | F19: 862.23 | G19: =E19*F19 -> 176412.26 | H19: 204.6 | I19: 862.23 | J19: =H19*I19 -> 176412.26 | L19: =IF(K19<>"",K19,I19) -> 862.23 | M19: =H19*L19 -> 176412.26 | N19: =M19-G19 -> 0 | O19: =IF(F19>0,L19/F19-1,"") -> 0 | P19: Без изменений
A20: 1. Вентиляция | B20: 1.16 | C20: Воздуховод(класс герм. "В") толщина лист. стали b-0,6мм 250 | D20: м | E20: 4.4 | F20: 1077.79 | G20: =E20*F20 -> 4742.276 | H20: 4.4 | I20: 1077.79 | J20: =H20*I20 -> 4742.276 | L20: =IF(K20<>"",K20,I20) -> 1077.79 | M20: =H20*L20 -> 4742.276 | N20: =M20-G20 -> 0 | O20: =IF(F20>0,L20/F20-1,"") -> 0 | P20: Без изменений
A21: 1. Вентиляция | B21: 1.17 | C21: Тройник ф 160 | D21: шт. | E21: 155 | F21: 855 | G21: =E21*F21 -> 132525 | H21: 155 | I21: 855 | J21: =H21*I21 -> 132525 | L21: =IF(K21<>"",K21,I21) -> 855 | M21: =H21*L21 -> 132525 | N21: =M21-G21 -> 0 | O21: =IF(F21>0,L21/F21-1,"") -> 0 | P21: Без изменений
A22: 1. Вентиляция | B22: 1.18 | C22: Тройник ф 200 | D22: шт. | E22: 7 | F22: 855 | G22: =E22*F22 -> 5985 | H22: 7 | I22: 855 | J22: =H22*I22 -> 5985 | L22: =IF(K22<>"",K22,I22) -> 855 | M22: =H22*L22 -> 5985 | N22: =M22-G22 -> 0 | O22: =IF(F22>0,L22/F22-1,"") -> 0 | P22: Без изменений
A23: 1. Вентиляция | B23: 1.19 | C23: Переход 160-200 | D23: шт. | E23: 104 | F23: 855 | G23: =E23*F23 -> 88920 | H23: 104 | I23: 855 | J23: =H23*I23 -> 88920 | L23: =IF(K23<>"",K23,I23) -> 855 | M23: =H23*L23 -> 88920 | N23: =M23-G23 -> 0 | O23: =IF(F23>0,L23/F23-1,"") -> 0 | P23: Без изменений
A24: 1. Вентиляция | B24: 1.20 | C24: Отвод 90 ф160 | D24: шт. | E24: 272 | F24: 855 | G24: =E24*F24 -> 232560 | H24: 272 | I24: 855 | J24: =H24*I24 -> 232560 | L24: =IF(K24<>"",K24,I24) -> 855 | M24: =H24*L24 -> 232560 | N24: =M24-G24 -> 0 | O24: =IF(F24>0,L24/F24-1,"") -> 0 | P24: Без изменений
A25: 1. Вентиляция | B25: 1.21 | C25: Отвод 45 Ф160 | D25: шт. | E25: 243 | F25: 855 | G25: =E25*F25 -> 207765 | H25: 243 | I25: 855 | J25: =H25*I25 -> 207765 | L25: =IF(K25<>"",K25,I25) -> 855 | M25: =H25*L25 -> 207765 | N25: =M25-G25 -> 0 | O25: =IF(F25>0,L25/F25-1,"") -> 0 | P25: Без изменений
A26: 1. Вентиляция | B26: 1.22 | C26: Тройник 200/160/200 исключено | D26: шт. | E26: 0 | F26: 0 | G26: =E26*F26 -> 0 | H26: 0 | J26: =H26*I26 -> 0 | L26: =IF(K26<>"",K26,I26) -> 0 | M26: =H26*L26 -> 0 | N26: =M26-G26 -> 0 | O26: =IF(F26>0,L26/F26-1,"") | P26: Без изменений
A27: 1. Вентиляция | B27: 1.23 | C27: КВК ф250 исключено | D27: шт. | E27: 0 | F27: 0 | G27: =E27*F27 -> 0 | H27: 0 | J27: =H27*I27 -> 0 | L27: =IF(K27<>"",K27,I27) -> 0 | M27: =H27*L27 -> 0 | N27: =M27-G27 -> 0 | O27: =IF(F27>0,L27/F27-1,"") | P27: Без изменений
A28: 1. Вентиляция | B28: 1.24 | C28: Переход с воздуховодов на врезку балки | D28: шт. | E28: 340 | F28: 950 | G28: =E28*F28 -> 323000 | H28: 340 | I28: 950 | J28: =H28*I28 -> 323000 | L28: =IF(K28<>"",K28,I28) -> 950 | M28: =H28*L28 -> 323000 | N28: =M28-G28 -> 0 | O28: =IF(F28>0,L28/F28-1,"") -> 0 | P28: Без изменений
A29: 1. Вентиляция | B29: 1.25 | C29: Отвод 90 ф200 | D29: шт. | E29: 32 | F29: 855 | G29: =E29*F29 -> 27360 | H29: 32 | I29: 855 | J29: =H29*I29 -> 27360 | L29: =IF(K29<>"",K29,I29) -> 855 | M29: =H29*L29 -> 27360 | N29: =M29-G29 -> 0 | O29: =IF(F29>0,L29/F29-1,"") -> 0 | P29: Без изменений
A30: 1. Вентиляция | B30: 1.26 | C30: Отвод 45 ф 200 | D30: шт. | E30: 113 | F30: 855 | G30: =E30*F30 -> 96615 | H30: 113 | I30: 855 | J30: =H30*I30 -> 96615 | L30: =IF(K30<>"",K30,I30) -> 855 | M30: =H30*L30 -> 96615 | N30: =M30-G30 -> 0 | O30: =IF(F30>0,L30/F30-1,"") -> 0 | P30: Без изменений
A31: 1. Вентиляция | B31: 1.27 | C31: КВК ф 200 исключено | D31: шт. | E31: 0 | F31: 0 | G31: =E31*F31 -> 0 | H31: 0 | J31: =H31*I31 -> 0 | L31: =IF(K31<>"",K31,I31) -> 0 | M31: =H31*L31 -> 0 | N31: =M31-G31 -> 0 | O31: =IF(F31>0,L31/F31-1,"") | P31: Без изменений
A32: 1. Вентиляция | B32: 1.28 | C32: КВК160 исключено | D32: шт. | E32: 0 | F32: 0 | G32: =E32*F32 -> 0 | H32: 0 | J32: =H32*I32 -> 0 | L32: =IF(K32<>"",K32,I32) -> 0 | M32: =H32*L32 -> 0 | N32: =M32-G32 -> 0 | O32: =IF(F32>0,L32/F32-1,"") | P32: Без изменений
A33: 1. Вентиляция | B33: 1.29 | C33: Отвод 90 ф100 | D33: шт. | E33: 2 | F33: 855 | G33: =E33*F33 -> 1710 | H33: 2 | I33: 855 | J33: =H33*I33 -> 1710 | L33: =IF(K33<>"",K33,I33) -> 855 | M33: =H33*L33 -> 1710 | N33: =M33-G33 -> 0 | O33: =IF(F33>0,L33/F33-1,"") -> 0 | P33: Без изменений
A34: 1. Вентиляция | B34: 1.30 | C34: Переход 250\200 | D34: шт. | E34: 10 | F34: 855 | G34: =E34*F34 -> 8550 | H34: 10 | I34: 855 | J34: =H34*I34 -> 8550 | L34: =IF(K34<>"",K34,I34) -> 855 | M34: =H34*L34 -> 8550 | N34: =M34-G34 -> 0 | O34: =IF(F34>0,L34/F34-1,"") -> 0 | P34: Без изменений
